Workbook

Sheet 📥 Respostas
A1: 📥 RESPOSTAS – Cole aqui os dados exportados do formulário
A2: Cole a partir da célula A3 incluindo os cabeçalhos. Setor deve estar na coluna D. Escala: Sempre / Frequentemente / Às vezes / Raramente / Nunca/Quase nunca
A3: Carimbo data/hora | B3: Pontuação | C3: Cargo / Função | D3: Setor | E3: Tempo na empresa | F3: Horas semanais | G3: Carga de trabalho mal distribuída | H3: Sem tempo para completar tarefas | I3: Necessidade de trabalhar rapidamente | J3: Trabalho exige atenção constante | K3: Trabalho exige decisões difíceis | L3: Trabalho exige emocionalmente | M3: Grau de influência no trabalho | N3: Trabalho exige iniciativa | O3: Trabalho permite aprender coisas novas | P3: Informado sobre decisões importantes | Q3: Recebe info necessária para trabalhar bem | R3: Sabe exatamente suas responsabilidades | S3: Reconhecimento pela gerência | T3: Tratamento justo no trabalho | U3: Ajuda e apoio do superior imediato | V3: Bom ambiente entre colegas | W3: Oportunidades de desenvolvimento | X3: Qualidade no planejamento (gestão) | Y3: Gerência confia nos funcionários | Z3: Confia nas informações da gerência | AA3: Conflitos resolvidos com justiça | AB3: Trabalho distribuído igualmente | AC3: Autoeficácia – resolve problemas | AD3: Significado do trabalho | AE3: Sente que o trabalho é importante | AF3: Identifica-se com os problemas da empresa | AG3: Satisfação global com o trabalho | AH3: Preocupação em ficar desempregado | AI3: Saúde geral percebida | AJ3: Trabalho afeta vida privada (energia) | AK3: Trabalho afeta vida privada (tempo) | AL3: Insônia / acorda durante a noite | AM3: Exaustão física | AN3: Exaustão emocional | AO3: Irritabilidade | AP3: Ansiedade | AQ3: Tristeza | AR3: Insultos ou provocações verbais | AS3: Assédio sexual indesejado | AT3: Ameaças de violência | AU3: Violência física

Sheet ⚙️ Config
A1: ⚙️ TABELA DE CONFIGURAÇÃO – Conversão de Escala
A3: Resposta Textual | B3: Score (1–5) | C3: Saúde – Resposta | D3: Score (1–5) | F3: Código | G3: Fator | H3: Questão (label curto) | I3: Coluna Respostas | J3: Direção (N/P/H)
A4: Sempre | B4: 5 | C4: Excelente | D4: 5 | F4: EL01 | G4: Exigência Laboral | H4: Carga de trabalho mal distribuída | I4: G | J4: N
A5: Frequentemente | B5: 4 | C5: Muito boa | D5: 4 | F5: EL02 | G5: Exigência Laboral | H5: Sem tempo para completar tarefas | I5: H | J5: N
A6: Às vezes | B6: 3 | C6: Boa | D6: 3 | F6: EL03 | G6: Exigência Laboral | H6: Necessidade de trabalhar rapidamente | I6: I | J6: N
A7: Ás vezes | B7: 3 | C7: Razoável | D7: 2 | F7: EL04 | G7: Exigência Laboral | H7: Trabalho exige atenção constante | I7: J | J7: N
A8: Algumas vezes | B8: 3 | C8: Fraca | D8: 1 | F8: EL05 | G8: Exigência Laboral | H8: Trabalho exige decisões difíceis | I8: K | J8: N
A9: Moderadamente | B9: 3 | C9: Excelente, Muito boa | D9: 4.5 | F9: EL06 | G9: Exigência Laboral | H9: Trabalho exige emocionalmente | I9: L | J9: N
A10: Um pouco | B10: 2 | C10: Muito boa, Boa | D10: 3.5 | F10: OT07 | G10: Organização do Trabalho | H10: Grau de influência no trabalho | I10: M | J10: P
A11: Raramente | B11: 2 | C11: Excelente, Boa | D11: 4 | F11: OT08 | G11: Organização do Trabalho | H11: Trabalho exige iniciativa | I11: N | J11: P
A12: Nunca / Quase nunca | B12: 1 | F12: OT09 | G12: Organização do Trabalho | H12: Trabalho permite aprender coisas novas | I12: O | J12: P
A13: Nunca/Quase nunca | B13: 1 | F13: OT10 | G13: Organização do Trabalho | H13: Informado sobre decisões importantes | I13: P | J13: P
F14: OT11 | G14: Organização do Trabalho | H14: Recebe info necessária para trabalhar bem | I14: Q | J14: P
F15: OT12 | G15: Organização do Trabalho | H15: Sabe exatamente suas responsabilidades | I15: R | J15: P
F16: RS13 | G16: Relações Sociais e Liderança | H16: Reconhecimento pela gerência | I16: S | J16: P
F17: RS14 | G17: Relações Sociais e Liderança | H17: Tratamento justo no trabalho | I17: T | J17: P
F18: RS15 | G18: Relações Sociais e Liderança | H18: Ajuda e apoio do superior imediato | I18: U | J18: P
F19: RS16 | G19: Relações Sociais e Liderança | H19: Bom ambiente entre colegas | I19: V | J19: P
F20: RS17 | G20: Relações Sociais e Liderança | H20: Oportunidades de desenvolvimento | I20: W | J20: P
F21: RS18 | G21: Relações Sociais e Liderança | H21: Qualidade no planejamento (gestão) | I21: X | J21: P
F22: PE19 | G22: Personalidade / Valores | H22: Gerência confia nos funcionários | I22: Y | J22: P
F23: PE20 | G23: Personalidade / Valores | H23: Confia nas informações da gerência | I23: Z | J23: P
F24: PE21 | G24: Personalidade / Valores | H24: Conflitos resolvidos com justiça | I24: AA | J24: P
F25: PE22 | G25: Personalidade / Valores | H25: Trabalho distribuído igualmente | I25: AB | J25: P
... F44: CO41 | G44: Comportamentos Ofensivos | H44: Violência física | I44: AU | J44: N

Sheet 🔢 Cálculo
A1: 🔢 CONVERSÃO DE SCORE E CÁLCULO DE RISCO POR RESPONDENTE
A2: Convertido automaticamente a partir da aba Respostas. Não editar manualmente.
A3: Nº | B3: Setor | C3: Cargo | D3: EL01 Carga de trabalho mal distri | E3: EL02 Sem tempo para completar tar | F3: EL03 Necessidade de trabalhar rap | G3: EL04 Trabalho exige atenção const | H3: EL05 Trabalho exige decisões difí | I3: EL06 Trabalho exige emocionalment | J3: OT07 Grau de influência no trabal | K3: OT08 Trabalho exige iniciativa | L3: OT09 Trabalho permite aprender co | M3: OT10 Informado sobre decisões imp | N3: OT11 Recebe info necessária para | O3: OT12 Sabe exatamente suas respons | P3: RS13 Reconhecimento pela gerência | Q3: RS14 Tratamento justo no trabalho | R3: RS15 Ajuda e apoio do superior im | S3: RS16 Bom ambiente entre colegas | T3: RS17 Oportunidades de desenvolvim | U3: RS18 Qualidade no planejamento (g | V3: PE19 Gerência confia nos funcioná | W3: PE20 Confia nas informações da ge | X3: PE21 Conflitos resolvidos com jus | Y3: PE22 Trabalho distribuído igualme | Z3: PE23 Autoeficácia – resolve probl | AA3: IT24 Significado do trabalho | AB3: IT25 Sente que o trabalho é impor | AC3: IT26 Identifica-se com os problem | AD3: IT27 Satisfação global com o trab | AE3: IT28 Preocupação em ficar desempr | AF3: SB29 Saúde geral percebida | AG3: SB30 Trabalho afeta vida privada | AH3: SB31 Trabalho afeta vida privada | AI3: SB32 Insônia / acorda durante a n | AJ3: SB33 Exaustão física | AK3: SB34 Exaustão emocional | AL3: SB35 Irritabilidade | AM3: SB36 Ansiedade | AN3: SB37 Tristeza | AO3: CO38 Insultos ou provocações verb | AP3: CO39 Assédio sexual indesejado | AQ3: CO40 Ameaças de violência | AR3: CO41 Violência física
A4: =IF(ISBLANK('📥 Respostas'!D4),"",ROW()-3) | B4: ='📥 Respostas'!D4 -> 0 | C4: ='📥 Respostas'!C4 -> 0 | D4: =IFERROR(VLOOKUP(TRIM('📥 Respostas'!G4),'⚙️ Config'!$A$4:$B$13,2,0),"") | E4: =IFERROR(VLOOKUP(TRIM('📥 Respostas'!H4),'⚙️ Config'!$A$4:$B$13,2,0),"") | F4: =IFERROR(VLOOKUP(TRIM('📥 Respostas'!I4),'⚙️ Config'!$A$4:$B$13,2,0),"") | G4: =IFERROR(VLOOKUP(TRIM('📥 Respostas'!J4),'⚙️ Config'!$A$4:$B$13,2,0),"") | H4: =IFERROR(VLOOKUP(TRIM('📥 Respostas'!K4),'⚙️ Config'!$A$4:$B$13,2,0),"") | I4: =IFERROR(VLOOKUP(TRIM('📥 Respostas'!L4),'⚙️ Config'!$A$4:$B$13,2,0),"") | J4: =IFERROR(VLOOKUP(TRIM('📥 Respostas'!M4),'⚙️ Config'!$A$4:$B$13,2,0),"") | K4: =IFERROR(VLOOKUP(TRIM('📥 Respostas'!N4),'⚙️ Config'!$A$4:$B$13,2,0),"") | ... AE4: =IFERROR(VLOOKUP(TRIM('📥 Respostas'!AH4),'⚙️ Config'!$A$4:$B$13,2,0),"") | AF4: =IFERROR(VLOOKUP(TRIM('📥 Respostas'!AI4),'⚙️ Config'!$C$4:$D$11,2,0),"") | AG4: =IFERROR(VLOOKUP(TRIM('📥 Respostas'!AJ4),'⚙️ Config'!$A$4:$B$13,2,0),"") | AH4: =IFERROR(VLOOKUP(TRIM('📥 Respostas'!AK4),'⚙️ Config'!$A$4:$B$13,2,0),"") | AI4: =IFERROR(VLOOKUP(TRIM('📥 Respostas'!AL4),'⚙️ Config'!$A$4:$B$13,2,0),"") | AJ4: =IFERROR(VLOOKUP(TRIM('📥 Respostas'!AM4),'⚙️ Config'!$A$4:$B$13,2,0),"") | AK4: =IFERROR(VLOOKUP(TRIM('📥 Respostas'!AN4),'⚙️ Config'!$A$4:$B$13,2,0),"") | AL4: =IFERROR(VLOOKUP(TRIM('📥 Respostas'!AO4),'⚙️ Config'!$A$4:$B$13,2,0),"") | AM4: =IFERROR(VLOOKUP(TRIM('📥 Respostas'!AP4),'⚙️ Config'!$A$4:$B$13,2,0),"") | AN4: =IFERROR(VLOOKUP(TRIM('📥 Respostas'!AQ4),'⚙️ Config'!$A$4:$B$13,2,0),"") | ... AR4: =IFERROR(VLOOKUP(TRIM('📥 Respostas'!AU4),'⚙️ Config'!$A$4:$B$13,2,0),"")
A5: =IF(ISBLANK('📥 Respostas'!D5),"",ROW()-3) | B5: ='📥 Respostas'!D5 -> 0 | C5: ='📥 Respostas'!C5 -> 0 | D5: =IFERROR(VLOOKUP(TRIM('📥 Respostas'!G5),'⚙️ Config'!$A$4:$B$13,2,0),"") | E5: =IFERROR(VLOOKUP(TRIM('📥 Respostas'!H5),'⚙️ Config'!$A$4:$B$13,2,0),"") | F5: =IFERROR(VLOOKUP(TRIM('📥 Respostas'!I5),'⚙️ Config'!$A$4:$B$13,2,0),"") | G5: =IFERROR(VLOOKUP(TRIM('📥 Respostas'!J5),'⚙️ Config'!$A$4:$B$13,2,0),"") | H5: =IFERROR(VLOOKUP(TRIM('📥 Respostas'!K5),'⚙️ Config'!$A$4:$B$13,2,0),"") | I5: =IFERROR(VLOOKUP(TRIM('📥 Respostas'!L5),'⚙️ Config'!$A$4:$B$13,2,0),"") | J5: =IFERROR(VLOOKUP(TRIM('📥 Respostas'!M5),'⚙️ Config'!$A$4:$B$13,2,0),"") | K5: =IFERROR(VLOOKUP(TRIM('📥 Respostas'!N5),'⚙️ Config'!$A$4:$B$13,2,0),"") | ... AE5: =IFERROR(VLOOKUP(TRIM('📥 Respostas'!AH5),'⚙️ Config'!$A$4:$B$13,2,0),"") | AF5: =IFERROR(VLOOKUP(TRIM('📥 Respostas'!AI5),'⚙️ Config'!$C$4:$D$11,2,0),"") | AG5: =IFERROR(VLOOKUP(TRIM('📥 Respostas'!AJ5),'⚙️ Config'!$A$4:$B$13,2,0),"") | AH5: =IFERROR(VLOOKUP(TRIM('📥 Respostas'!AK5),'⚙️ Config'!$A$4:$B$13,2,0),"") | AI5: =IFERROR(VLOOKUP(TRIM('📥 Respostas'!AL5),'⚙️ Config'!$A$4:$B$13,2,0),"") | AJ5: =IFERROR(VLOOKUP(TRIM('📥 Respostas'!AM5),'⚙️ Config'!$A$4:$B$13,2,0),"") | AK5: =IFERROR(VLOOKUP(TRIM('📥 Respostas'!AN5),'⚙️ Config'!$A$4:$B$13,2,0),"") | AL5: =IFERROR(VLOOKUP(TRIM('📥 Respostas'!AO5),'⚙️ Config'!$A$4:$B$13,2,0),"") | AM5: =IFERROR(VLOOKUP(TRIM('📥 Respostas'!AP5),'⚙️ Config'!$A$4:$B$13,2,0),"") | AN5: =IFERROR(VLOOKUP(TRIM('📥 Respostas'!AQ5),'⚙️ Config'!$A$4:$B$13,2,0),"") | ... AR5: =IFERROR(VLOOKUP(TRIM('📥 Respostas'!AU5),'⚙️ Config'!$A$4:$B$13,2,0),"")
A6: =IF(ISBLANK('📥 Respostas'!D6),"",ROW()-3) | B6: ='📥 Respostas'!D6 -> 0 | C6: ='📥 Respostas'!C6 -> 0 | D6: =IFERROR(VLOOKUP(TRIM('📥 Respostas'!G6),'⚙️ Config'!$A$4:$B$13,2,0),"") | E6: =IFERROR(VLOOKUP(TRIM('📥 Respostas'!H6),'⚙️ Config'!$A$4:$B$13,2,0),"") | F6: =IFERROR(VLOOKUP(TRIM('📥 Respostas'!I6),'⚙️ Config'!$A$4:$B$13,2,0),"") | G6: =IFERROR(VLOOKUP(TRIM('📥 Respostas'!J6),'⚙️ Config'!$A$4:$B$13,2,0),"") | H6: =IFERROR(VLOOKUP(TRIM('📥 Respostas'!K6),'⚙️ Config'!$A$4:$B$13,2,0),"") | I6: =IFERROR(VLOOKUP(TRIM('📥 Respostas'!L6),'⚙️ Config'!$A$4:$B$13,2,0),"") | J6: =IFERROR(VLOOKUP(TRIM('📥 Respostas'!M6),'⚙️ Config'!$A$4:$B$13,2,0),"") | K6: =IFERROR(VLOOKUP(TRIM('📥 Respostas'!N6),'⚙️ Config'!$A$4:$B$13,2,0),"") | ... AE6: =IFERROR(VLOOKUP(TRIM('📥 Respostas'!AH6),'⚙️ Config'!$A$4:$B$13,2,0),"") | AF6: =IFERROR(VLOOKUP(TRIM('📥 Respostas'!AI6),'⚙️ Config'!$C$4:$D$11,2,0),"") | AG6: =IFERROR(VLOOKUP(TRIM('📥 Respostas'!AJ6),'⚙️ Config'!$A$4:$B$13,2,0),"") | AH6: =IFERROR(VLOOKUP(TRIM('📥 Respostas'!AK6),'⚙️ Config'!$A$4:$B$13,2,0),"") | AI6: =IFERROR(VLOOKUP(TRIM('📥 Respostas'!AL6),'⚙️ Config'!$A$4:$B$13,2,0),"") | AJ6: =IFERROR(VLOOKUP(TRIM('📥 Respostas'!AM6),'⚙️ Config'!$A$4:$B$13,2,0),"") | AK6: =IFERROR(VLOOKUP(TRIM('📥 Respostas'!AN6),'⚙️ Config'!$A$4:$B$13,2,0),"") | AL6: =IFERROR(VLOOKUP(TRIM('📥 Respostas'!AO6),'⚙️ Config'!$A$4:$B$13,2,0),"") | AM6: =IFERROR(VLOOKUP(TRIM('📥 Respostas'!AP6),'⚙️ Config'!$A$4:$B$13,2,0),"") | AN6: =IFERROR(VLOOKUP(TRIM('📥 Respostas'!AQ6),'⚙️ Config'!$A$4:$B$13,2,0),"") | ... AR6: =IFERROR(VLOOKUP(TRIM('📥 Respostas'!AU6),'⚙️ Config'!$A$4:$B$13,2,0),"")
A7: =IF(ISBLANK('📥 Respostas'!D7),"",ROW()-3) | B7: ='📥 Respostas'!D7 -> 0 | C7: ='📥 Respostas'!C7 -> 0 | D7: =IFERROR(VLOOKUP(TRIM('📥 Respostas'!G7),'⚙️ Config'!$A$4:$B$13,2,0),"") | E7: =IFERROR(VLOOKUP(TRIM('📥 Respostas'!H7),'⚙️ Config'!$A$4:$B$13,2,0),"") | F7: =IFERROR(VLOOKUP(TRIM('📥 Respostas'!I7),'⚙️ Config'!$A$4:$B$13,2,0),"") | G7: =IFERROR(VLOOKUP(TRIM('📥 Respostas'!J7),'⚙️ Config'!$A$4:$B$13,2,0),"") | H7: =IFERROR(VLOOKUP(TRIM('📥 Respostas'!K7),'⚙️ Config'!$A$4:$B$13,2,0),"") | I7: =IFERROR(VLOOKUP(TRIM('📥 Respostas'!L7),'⚙️ Config'!$A$4:$B$13,2,0),"") | J7: =IFERROR(VLOOKUP(TRIM('📥 Respostas'!M7),'⚙️ Config'!$A$4:$B$13,2,0),"") | K7: =IFERROR(VLOOKUP(TRIM('📥 Respostas'!N7),'⚙️ Config'!$A$4:$B$13,2,0),"") | ... AE7: =IFERROR(VLOOKUP(TRIM('📥 Respostas'!AH7),'⚙️ Config'!$A$4:$B$13,2,0),"") | AF7: =IFERROR(VLOOKUP(TRIM('📥 Respostas'!AI7),'⚙️ Config'!$C$4:$D$11,2,0),"") | AG7: =IFERROR(VLOOKUP(TRIM('📥 Respostas'!AJ7),'⚙️ Config'!$A$4:$B$13,2,0),"") | AH7: =IFERROR(VLOOKUP(TRIM('📥 Respostas'!AK7),'⚙️ Config'!$A$4:$B$13,2,0),"") | AI7: =IFERROR(VLOOKUP(TRIM('📥 Respostas'!AL7),'⚙️ Config'!$A$4:$B$13,2,0),"") | AJ7: =IFERROR(VLOOKUP(TRIM('📥 Respostas'!AM7),'⚙️ Config'!$A$4:$B$13,2,0),"") | AK7: =IFERROR(VLOOKUP(TRIM('📥 Respostas'!AN7),'⚙️ Config'!$A$4:$B$13,2,0),"") | AL7: =IFERROR(VLOOKUP(TRIM('📥 Respostas'!AO7),'⚙️ Config'!$A$4:$B$13,2,0),"") | AM7: =IFERROR(VLOOKUP(TRIM('📥 Respostas'!AP7),'⚙️ Config'!$A$4:$B$13,2,0),"") | AN7: =IFERROR(VLOOKUP(TRIM('📥 Respostas'!AQ7),'⚙️ Config'!$A$4:$B$13,2,0),"") | ... AR7: =IFERROR(VLOOKUP(TRIM('📥 Respostas'!AU7),'⚙️ Config'!$A$4:$B$13,2,0),"")
A8: =IF(ISBLANK('📥 Respostas'!D8),"",ROW()-3) | B8: ='📥 Respostas'!D8 -> 0 | C8: ='📥 Respostas'!C8 -> 0 | D8: =IFERROR(VLOOKUP(TRIM('📥 Respostas'!G8),'⚙️ Config'!$A$4:$B$13,2,0),"") | E8: =IFERROR(VLOOKUP(TRIM('📥 Respostas'!H8),'⚙️ Config'!$A$4:$B$13,2,0),"") | F8: =IFERROR(VLOOKUP(TRIM('📥 Respostas'!I8),'⚙️ Config'!$A$4:$B$13,2,0),"") | G8: =IFERROR(VLOOKUP(TRIM('📥 Respostas'!J8),'⚙️ Config'!$A$4:$B$13,2,0),"") | H8: =IFERROR(VLOOKUP(TRIM('📥 Respostas'!K8),'⚙️ Config'!$A$4:$B$13,2,0),"") | I8: =IFERROR(VLOOKUP(TRIM('📥 Respostas'!L8),'⚙️ Config'!$A$4:$B$13,2,0),"") | J8: =IFERROR(VLOOKUP(TRIM('📥 Respostas'!M8),'⚙️ Config'!$A$4:$B$13,2,0),"") | K8: =IFERROR(VLOOKUP(TRIM('📥 Respostas'!N8),'⚙️ Config'!$A$4:$B$13,2,0),"") | ... AE8: =IFERROR(VLOOKUP(TRIM('📥 Respostas'!AH8),'⚙️ Config'!$A$4:$B$13,2,0),"") | AF8: =IFERROR(VLOOKUP(TRIM('📥 Respostas'!AI8),'⚙️ Config'!$C$4:$D$11,2,0),"") | AG8: =IFERROR(VLOOKUP(TRIM('📥 Respostas'!AJ8),'⚙️ Config'!$A$4:$B$13,2,0),"") | AH8: =IFERROR(VLOOKUP(TRIM('📥 Respostas'!AK8),'⚙️ Config'!$A$4:$B$13,2,0),"") | AI8: =IFERROR(VLOOKUP(TRIM('📥 Respostas'!AL8),'⚙️ Config'!$A$4:$B$13,2,0),"") | AJ8: =IFERROR(VLOOKUP(TRIM('📥 Respostas'!AM8),'⚙️ Config'!$A$4:$B$13,2,0),"") | AK8: =IFERROR(VLOOKUP(TRIM('📥 Respostas'!AN8),'⚙️ Config'!$A$4:$B$13,2,0),"") | AL8: =IFERROR(VLOOKUP(TRIM('📥 Respostas'!AO8),'⚙️ Config'!$A$4:$B$13,2,0),"") | AM8: =IFERROR(VLOOKUP(TRIM('📥 Respostas'!AP8),'⚙️ Config'!$A$4:$B$13,2,0),"") | AN8: =IFERROR(VLOOKUP(TRIM('📥 Respostas'!AQ8),'⚙️ Config'!$A$4:$B$13,2,0),"") | ... AR8: =IFERROR(VLOOKUP(TRIM('📥 Respostas'!AU8),'⚙️ Config'!$A$4:$B$13,2,0),"")
A9: =IF(ISBLANK('📥 Respostas'!D9),"",ROW()-3) | B9: ='📥 Respostas'!D9 -> 0 | C9: ='📥 Respostas'!C9 -> 0 | D9: =IFERROR(VLOOKUP(TRIM('📥 Respostas'!G9),'⚙️ Config'!$A$4:$B$13,2,0),"") | E9: =IFERROR(VLOOKUP(TRIM('📥 Respostas'!H9),'⚙️ Config'!$A$4:$B$13,2,0),"") | F9: =IFERROR(VLOOKUP(TRIM('📥 Respostas'!I9),'⚙️ Config'!$A$4:$B$13,2,0),"") | G9: =IFERROR(VLOOKUP(TRIM('📥 Respostas'!J9),'⚙️ Config'!$A$4:$B$13,2,0),"") | H9: =IFERROR(VLOOKUP(TRIM('📥 Respostas'!K9),'⚙️ Config'!$A$4:$B$13,2,0),"") | I9: =IFERROR(VLOOKUP(TRIM('📥 Respostas'!L9),'⚙️ Config'!$A$4:$B$13,2,0),"") | J9: =IFERROR(VLOOKUP(TRIM('📥 Respostas'!M9),'⚙️ Config'!$A$4:$B$13,2,0),"") | K9: =IFERROR(VLOOKUP(TRIM('📥 Respostas'!N9),'⚙️ Config'!$A$4:$B$13,2,0),"") | ... AE9: =IFERROR(VLOOKUP(TRIM('📥 Respostas'!AH9),'⚙️ Config'!$A$4:$B$13,2,0),"") | AF9: =IFERROR(VLOOKUP(TRIM('📥 Respostas'!AI9),'⚙️ Config'!$C$4:$D$11,2,0),"") | AG9: =IFERROR(VLOOKUP(TRIM('📥 Respostas'!AJ9),'⚙️ Config'!$A$4:$B$13,2,0),"") | AH9: =IFERROR(VLOOKUP(TRIM('📥 Respostas'!AK9),'⚙️ Config'!$A$4:$B$13,2,0),"") | AI9: =IFERROR(VLOOKUP(TRIM('📥 Respostas'!AL9),'⚙️ Config'!$A$4:$B$13,2,0),"") | AJ9: =IFERROR(VLOOKUP(TRIM('📥 Respostas'!AM9),'⚙️ Config'!$A$4:$B$13,2,0),"") | AK9: =IFERROR(VLOOKUP(TRIM('📥 Respostas'!AN9),'⚙️ Config'!$A$4:$B$13,2,0),"") | AL9: =IFERROR(VLOOKUP(TRIM('📥 Respostas'!AO9),'⚙️ Config'!$A$4:$B$13,2,0),"") | AM9: =IFERROR(VLOOKUP(TRIM('📥 Respostas'!AP9),'⚙️ Config'!$A$4:$B$13,2,0),"") | AN9: =IFERROR(VLOOKUP(TRIM('📥 Respostas'!AQ9),'⚙️ Config'!$A$4:$B$13,2,0),"") | ... AR9: =IFERROR(VLOOKUP(TRIM('📥 Respostas'!AU9),'⚙️ Config'!$A$4:$B$13,2,0),"")
A10: =IF(ISBLANK('📥 Respostas'!D10),"",ROW()-3) | B10: ='📥 Respostas'!D10 -> 0 | C10: ='📥 Respostas'!C10 -> 0 | D10: =IFERROR(VLOOKUP(TRIM('📥 Respostas'!G10),'⚙️ Config'!$A$4:$B$13,2,0),"") | E10: =IFERROR(VLOOKUP(TRIM('📥 Respostas'!H10),'⚙️ Config'!$A$4:$B$13,2,0),"") | F10: =IFERROR(VLOOKUP(TRIM('📥 Respostas'!I10),'⚙️ Config'!$A$4:$B$13,2,0),"") | G10: =IFERROR(VLOOKUP(TRIM('📥 Respostas'!J10),'⚙️ Config'!$A$4:$B$13,2,0),"") | H10: =IFERROR(VLOOKUP(TRIM('📥 Respostas'!K10),'⚙️ Config'!$A$4:$B$13,2,0),"") | I10: =IFERROR(VLOOKUP(TRIM('📥 Respostas'!L10),'⚙️ Config'!$A$4:$B$13,2,0),"") | J10: =IFERROR(VLOOKUP(TRIM('📥 Respostas'!M10),'⚙️ Config'!$A$4:$B$13,2,0),"") | K10: =IFERROR(VLOOKUP(TRIM('📥 Respostas'!N10),'⚙️ Config'!$A$4:$B$13,2,0),"") | ... AE10: =IFERROR(VLOOKUP(TRIM('📥 Respostas'!AH10),'⚙️ Config'!$A$4:$B$13,2,0),"") | AF10: =IFERROR(VLOOKUP(TRIM('📥 Respostas'!AI10),'⚙️ Config'!$C$4:$D$11,2,0),"") | AG10: =IFERROR(VLOOKUP(TRIM('📥 Respostas'!AJ10),'⚙️ Config'!$A$4:$B$13,2,0),"") | AH10: =IFERROR(VLOOKUP(TRIM('📥 Respostas'!AK10),'⚙️ Config'!$A$4:$B$13,2,0),"") | AI10: =IFERROR(VLOOKUP(TRIM('📥 Respostas'!AL10),'⚙️ Config'!$A$4:$B$13,2,0),"") | AJ10: =IFERROR(VLOOKUP(TRIM('📥 Respostas'!AM10),'⚙️ Config'!$A$4:$B$13,2,0),"") | AK10: =IFERROR(VLOOKUP(TRIM('📥 Respostas'!AN10),'⚙️ Config'!$A$4:$B$13,2,0),"") | AL10: =IFERROR(VLOOKUP(TRIM('📥 Respostas'!AO10),'⚙️ Config'!$A$4:$B$13,2,0),"") | AM10: =IFERROR(VLOOKUP(TRIM('📥 Respostas'!AP10),'⚙️ Config'!$A$4:$B$13,2,0),"") | AN10: =IFERROR(VLOOKUP(TRIM('📥 Respostas'!AQ10),'⚙️ Config'!$A$4:$B$13,2,0),"") | ... AR10: =IFERROR(VLOOKUP(TRIM('📥 Respostas'!AU10),'⚙️ Config'!$A$4:$B$13,2,0),"")
A11: =IF(ISBLANK('📥 Respostas'!D11),"",ROW()-3) | B11: ='📥 Respostas'!D11 -> 0 | C11: ='📥 Respostas'!C11 -> 0 | D11: =IFERROR(VLOOKUP(TRIM('📥 Respostas'!G11),'⚙️ Config'!$A$4:$B$13,2,0),"") | E11: =IFERROR(VLOOKUP(TRIM('📥 Respostas'!H11),'⚙️ Config'!$A$4:$B$13,2,0),"") | F11: =IFERROR(VLOOKUP(TRIM('📥 Respostas'!I11),'⚙️ Config'!$A$4:$B$13,2,0),"") | G11: =IFERROR(VLOOKUP(TRIM('📥 Respostas'!J11),'⚙️ Config'!$A$4:$B$13,2,0),"") | H11: =IFERROR(VLOOKUP(TRIM('📥 Respostas'!K11),'⚙️ Config'!$A$4:$B$13,2,0),"") | I11: =IFERROR(VLOOKUP(TRIM('📥 Respostas'!L11),'⚙️ Config'!$A$4:$B$13,2,0),"") | J11: =IFERROR(VLOOKUP(TRIM('📥 Respostas'!M11),'⚙️ Config'!$A$4:$B$13,2,0),"") | K11: =IFERROR(VLOOKUP(TRIM('📥 Respostas'!N11),'⚙️ Config'!$A$4:$B$13,2,0),"") | ... AE11: =IFERROR(VLOOKUP(TRIM('📥 Respostas'!AH11),'⚙️ Config'!$A$4:$B$13,2,0),"") | AF11: =IFERROR(VLOOKUP(TRIM('📥 Respostas'!AI11),'⚙️ Config'!$C$4:$D$11,2,0),"") | AG11: =IFERROR(VLOOKUP(TRIM('📥 Respostas'!AJ11),'⚙️ Config'!$A$4:$B$13,2,0),"") | AH11: =IFERROR(VLOOKUP(TRIM('📥 Respostas'!AK11),'⚙️ Config'!$A$4:$B$13,2,0),"") | AI11: =IFERROR(VLOOKUP(TRIM('📥 Respostas'!AL11),'⚙️ Config'!$A$4:$B$13,2,0),"") | AJ11: =IFERROR(VLOOKUP(TRIM('📥 Respostas'!AM11),'⚙️ Config'!$A$4:$B$13,2,0),"") | AK11: =IFERROR(VLOOKUP(TRIM('📥 Respostas'!AN11),'⚙️ Config'!$A$4:$B$13,2,0),"") | AL11: =IFERROR(VLOOKUP(TRIM('📥 Respostas'!AO11),'⚙️ Config'!$A$4:$B$13,2,0),"") | AM11: =IFERROR(VLOOKUP(TRIM('📥 Respostas'!AP11),'⚙️ Config'!$A$4:$B$13,2,0),"") | AN11: =IFERROR(VLOOKUP(TRIM('📥 Respostas'!AQ11),'⚙️ Config'!$A$4:$B$13,2,0),"") | ... AR11: =IFERROR(VLOOKUP(TRIM('📥 Respostas'!AU11),'⚙️ Config'!$A$4:$B$13,2,0),"")
A12: =IF(ISBLANK('📥 Respostas'!D12),"",ROW()-3) | B12: ='📥 Respostas'!D12 -> 0 | C12: ='📥 Respostas'!C12 -> 0 | D12: =IFERROR(VLOOKUP(TRIM('📥 Respostas'!G12),'⚙️ Config'!$A$4:$B$13,2,0),"") | E12: =IFERROR(VLOOKUP(TRIM('📥 Respostas'!H12),'⚙️ Config'!$A$4:$B$13,2,0),"") | F12: =IFERROR(VLOOKUP(TRIM('📥 Respostas'!I12),'⚙️ Config'!$A$4:$B$13,2,0),"") | G12: =IFERROR(VLOOKUP(TRIM('📥 Respostas'!J12),'⚙️ Config'!$A$4:$B$13,2,0),"") | H12: =IFERROR(VLOOKUP(TRIM('📥 Respostas'!K12),'⚙️ Config'!$A$4:$B$13,2,0),"") | I12: =IFERROR(VLOOKUP(TRIM('📥 Respostas'!L12),'⚙️ Config'!$A$4:$B$13,2,0),"") | J12: =IFERROR(VLOOKUP(TRIM('📥 Respostas'!M12),'⚙️ Config'!$A$4:$B$13,2,0),"") | K12: =IFERROR(VLOOKUP(TRIM('📥 Respostas'!N12),'⚙️ Config'!$A$4:$B$13,2,0),"") | ... AE12: =IFERROR(VLOOKUP(TRIM('📥 Respostas'!AH12),'⚙️ Config'!$A$4:$B$13,2,0),"") | AF12: =IFERROR(VLOOKUP(TRIM('📥 Respostas'!AI12),'⚙️ Config'!$C$4:$D$11,2,0),"") | AG12: =IFERROR(VLOOKUP(TRIM('📥 Respostas'!AJ12),'⚙️ Config'!$A$4:$B$13,2,0),"") | AH12: =IFERROR(VLOOKUP(TRIM('📥 Respostas'!AK12),'⚙️ Config'!$A$4:$B$13,2,0),"") | AI12: =IFERROR(VLOOKUP(TRIM('📥 Respostas'!AL12),'⚙️ Config'!$A$4:$B$13,2,0),"") | AJ12: =IFERROR(VLOOKUP(TRIM('📥 Respostas'!AM12),'⚙️ Config'!$A$4:$B$13,2,0),"") | AK12: =IFERROR(VLOOKUP(TRIM('📥 Respostas'!AN12),'⚙️ Config'!$A$4:$B$13,2,0),"") | AL12: =IFERROR(VLOOKUP(TRIM('📥 Respostas'!AO12),'⚙️ Config'!$A$4:$B$13,2,0),"") | AM12: =IFERROR(VLOOKUP(TRIM('📥 Respostas'!AP12),'⚙️ Config'!$A$4:$B$13,2,0),"") | AN12: =IFERROR(VLOOKUP(TRIM('📥 Respostas'!AQ12),'⚙️ Config'!$A$4:$B$13,2,0),"") | ... AR12: =IFERROR(VLOOKUP(TRIM('📥 Respostas'!AU12),'⚙️ Config'!$A$4:$B$13,2,0),"")
A13: =IF(ISBLANK('📥 Respostas'!D13),"",ROW()-3) | B13: ='📥 Respostas'!D13 -> 0 | C13: ='📥 Respostas'!C13 -> 0 | D13: =IFERROR(VLOOKUP(TRIM('📥 Respostas'!G13),'⚙️ Config'!$A$4:$B$13,2,0),"") | E13: =IFERROR(VLOOKUP(TRIM('📥 Respostas'!H13),'⚙️ Config'!$A$4:$B$13,2,0),"") | F13: =IFERROR(VLOOKUP(TRIM('📥 Respostas'!I13),'⚙️ Config'!$A$4:$B$13,2,0),"") | G13: =IFERROR(VLOOKUP(TRIM('📥 Respostas'!J13),'⚙️ Config'!$A$4:$B$13,2,0),"") | H13: =IFERROR(VLOOKUP(TRIM('📥 Respostas'!K13),'⚙️ Config'!$A$4:$B$13,2,0),"") | I13: =IFERROR(VLOOKUP(TRIM('📥 Respostas'!L13),'⚙️ Config'!$A$4:$B$13,2,0),"") | J13: =IFERROR(VLOOKUP(TRIM('📥 Respostas'!M13),'⚙️ Config'!$A$4:$B$13,2,0),"") | K13: =IFERROR(VLOOKUP(TRIM('📥 Respostas'!N13),'⚙️ Config'!$A$4:$B$13,2,0),"") | ... AE13: =IFERROR(VLOOKUP(TRIM('📥 Respostas'!AH13),'⚙️ Config'!$A$4:$B$13,2,0),"") | AF13: =IFERROR(VLOOKUP(TRIM('📥 Respostas'!AI13),'⚙️ Config'!$C$4:$D$11,2,0),"") | AG13: =IFERROR(VLOOKUP(TRIM('📥 Respostas'!AJ13),'⚙️ Config'!$A$4:$B$13,2,0),"") | AH13: =IFERROR(VLOOKUP(TRIM('📥 Respostas'!AK13),'⚙️ Config'!$A$4:$B$13,2,0),"") | AI13: =IFERROR(VLOOKUP(TRIM('📥 Respostas'!AL13),'⚙️ Config'!$A$4:$B$13,2,0),"") | AJ13: =IFERROR(VLOOKUP(TRIM('📥 Respostas'!AM13),'⚙️ Config'!$A$4:$B$13,2,0),"") | AK13: =IFERROR(VLOOKUP(TRIM('📥 Respostas'!AN13),'⚙️ Config'!$A$4:$B$13,2,0),"") | AL13: =IFERROR(VLOOKUP(TRIM('📥 Respostas'!AO13),'⚙️ Config'!$A$4:$B$13,2,0),"") | AM13: =IFERROR(VLOOKUP(TRIM('📥 Respostas'!AP13),'⚙️ Config'!$A$4:$B$13,2,0),"") | AN13: =IFERROR(VLOOKUP(TRIM('📥 Respostas'!AQ13),'⚙️ Config'!$A$4:$B$13,2,0),"") | ... AR13: =IFERROR(VLOOKUP(TRIM('📥 Respostas'!AU13),'⚙️ Config'!$A$4:$B$13,2,0),"")
A14: =IF(ISBLANK('📥 Respostas'!D14),"",ROW()-3) | B14: ='📥 Respostas'!D14 -> 0 | C14: ='📥 Respostas'!C14 -> 0 | D14: =IFERROR(VLOOKUP(TRIM('📥 Respostas'!G14),'⚙️ Config'!$A$4:$B$13,2,0),"") | E14: =IFERROR(VLOOKUP(TRIM('📥 Respostas'!H14),'⚙️ Config'!$A$4:$B$13,2,0),"") | F14: =IFERROR(VLOOKUP(TRIM('📥 Respostas'!I14),'⚙️ Config'!$A$4:$B$13,2,0),"") | G14: =IFERROR(VLOOKUP(TRIM('📥 Respostas'!J14),'⚙️ Config'!$A$4:$B$13,2,0),"") | H14: =IFERROR(VLOOKUP(TRIM('📥 Respostas'!K14),'⚙️ Config'!$A$4:$B$13,2,0),"") | I14: =IFERROR(VLOOKUP(TRIM('📥 Respostas'!L14),'⚙️ Config'!$A$4:$B$13,2,0),"") | J14: =IFERROR(VLOOKUP(TRIM('📥 Respostas'!M14),'⚙️ Config'!$A$4:$B$13,2,0),"") | K14: =IFERROR(VLOOKUP(TRIM('📥 Respostas'!N14),'⚙️ Config'!$A$4:$B$13,2,0),"") | ... AE14: =IFERROR(VLOOKUP(TRIM('📥 Respostas'!AH14),'⚙️ Config'!$A$4:$B$13,2,0),"") | AF14: =IFERROR(VLOOKUP(TRIM('📥 Respostas'!AI14),'⚙️ Config'!$C$4:$D$11,2,0),"") | AG14: =IFERROR(VLOOKUP(TRIM('📥 Respostas'!AJ14),'⚙️ Config'!$A$4:$B$13,2,0),"") | AH14: =IFERROR(VLOOKUP(TRIM('📥 Respostas'!AK14),'⚙️ Config'!$A$4:$B$13,2,0),"") | AI14: =IFERROR(VLOOKUP(TRIM('📥 Respostas'!AL14),'⚙️ Config'!$A$4:$B$13,2,0),"") | AJ14: =IFERROR(VLOOKUP(TRIM('📥 Respostas'!AM14),'⚙️ Config'!$A$4:$B$13,2,0),"") | AK14: =IFERROR(VLOOKUP(TRIM('📥 Respostas'!AN14),'⚙️ Config'!$A$4:$B$13,2,0),"") | AL14: =IFERROR(VLOOKUP(TRIM('📥 Respostas'!AO14),'⚙️ Config'!$A$4:$B$13,2,0),"") | AM14: =IFERROR(VLOOKUP(TRIM('📥 Respostas'!AP14),'⚙️ Config'!$A$4:$B$13,2,0),"") | AN14: =IFERROR(VLOOKUP(TRIM('📥 Respostas'!AQ14),'⚙️ Config'!$A$4:$B$13,2,0),"") | ... AR14: =IFERROR(VLOOKUP(TRIM('📥 Respostas'!AU14),'⚙️ Config'!$A$4:$B$13,2,0),"")
A15: =IF(ISBLANK('📥 Respostas'!D15),"",ROW()-3) | B15: ='📥 Respostas'!D15 -> 0 | C15: ='📥 Respostas'!C15 -> 0 | D15: =IFERROR(VLOOKUP(TRIM('📥 Respostas'!G15),'⚙️ Config'!$A$4:$B$13,2,0),"") | E15: =IFERROR(VLOOKUP(TRIM('📥 Respostas'!H15),'⚙️ Config'!$A$4:$B$13,2,0),"") | F15: =IFERROR(VLOOKUP(TRIM('📥 Respostas'!I15),'⚙️ Config'!$A$4:$B$13,2,0),"") | G15: =IFERROR(VLOOKUP(TRIM('📥 Respostas'!J15),'⚙️ Config'!$A$4:$B$13,2,0),"") | H15: =IFERROR(VLOOKUP(TRIM('📥 Respostas'!K15),'⚙️ Config'!$A$4:$B$13,2,0),"") | I15: =IFERROR(VLOOKUP(TRIM('📥 Respostas'!L15),'⚙️ Config'!$A$4:$B$13,2,0),"") | J15: =IFERROR(VLOOKUP(TRIM('📥 Respostas'!M15),'⚙️ Config'!$A$4:$B$13,2,0),"") | K15: =IFERROR(VLOOKUP(TRIM('📥 Respostas'!N15),'⚙️ Config'!$A$4:$B$13,2,0),"") | ... AE15: =IFERROR(VLOOKUP(TRIM('📥 Respostas'!AH15),'⚙️ Config'!$A$4:$B$13,2,0),"") | AF15: =IFERROR(VLOOKUP(TRIM('📥 Respostas'!AI15),'⚙️ Config'!$C$4:$D$11,2,0),"") | AG15: =IFERROR(VLOOKUP(TRIM('📥 Respostas'!AJ15),'⚙️ Config'!$A$4:$B$13,2,0),"") | AH15: =IFERROR(VLOOKUP(TRIM('📥 Respostas'!AK15),'⚙️ Config'!$A$4:$B$13,2,0),"") | AI15: =IFERROR(VLOOKUP(TRIM('📥 Respostas'!AL15),'⚙️ Config'!$A$4:$B$13,2,0),"") | AJ15: =IFERROR(VLOOKUP(TRIM('📥 Respostas'!AM15),'⚙️ Config'!$A$4:$B$13,2,0),"") | AK15: =IFERROR(VLOOKUP(TRIM('📥 Respostas'!AN15),'⚙️ Config'!$A$4:$B$13,2,0),"") | AL15: =IFERROR(VLOOKUP(TRIM('📥 Respostas'!AO15),'⚙️ Config'!$A$4:$B$13,2,0),"") | AM15: =IFERROR(VLOOKUP(TRIM('📥 Respostas'!AP15),'⚙️ Config'!$A$4:$B$13,2,0),"") | AN15: =IFERROR(VLOOKUP(TRIM('📥 Respostas'!AQ15),'⚙️ Config'!$A$4:$B$13,2,0),"") | ... AR15: =IFERROR(VLOOKUP(TRIM('📥 Respostas'!AU15),'⚙️ Config'!$A$4:$B$13,2,0),"")
... A203: =IF(ISBLANK('📥 Respostas'!D203),"",ROW()-3) | B203: ='📥 Respostas'!D203 -> 0 | C203: ='📥 Respostas'!C203 -> 0 | D203: =IFERROR(VLOOKUP(TRIM('📥 Respostas'!G203),'⚙️ Config'!$A$4:$B$13,2,0),"") | E203: =IFERROR(VLOOKUP(TRIM('📥 Respostas'!H203),'⚙️ Config'!$A$4:$B$13,2,0),"") | F203: =IFERROR(VLOOKUP(TRIM('📥 Respostas'!I203),'⚙️ Config'!$A$4:$B$13,2,0),"") | G203: =IFERROR(VLOOKUP(TRIM('📥 Respostas'!J203),'⚙️ Config'!$A$4:$B$13,2,0),"") | H203: =IFERROR(VLOOKUP(TRIM('📥 Respostas'!K203),'⚙️ Config'!$A$4:$B$13,2,0),"") | I203: =IFERROR(VLOOKUP(TRIM('📥 Respostas'!L203),'⚙️ Config'!$A$4:$B$13,2,0),"") | J203: =IFERROR(VLOOKUP(TRIM('📥 Respostas'!M203),'⚙️ Config'!$A$4:$B$13,2,0),"") | K203: =IFERROR(VLOOKUP(TRIM('📥 Respostas'!N203),'⚙️ Config'!$A$4:$B$13,2,0),"") | ... AE203: =IFERROR(VLOOKUP(TRIM('📥 Respostas'!AH203),'⚙️ Config'!$A$4:$B$13,2,0),"") | AF203: =IFERROR(VLOOKUP(TRIM('📥 Respostas'!AI203),'⚙️ Config'!$C$4:$D$11,2,0),"") | AG203: =IFERROR(VLOOKUP(TRIM('📥 Respostas'!AJ203),'⚙️ Config'!$A$4:$B$13,2,0),"") | AH203: =IFERROR(VLOOKUP(TRIM('📥 Respostas'!AK203),'⚙️ Config'!$A$4:$B$13,2,0),"") | AI203: =IFERROR(VLOOKUP(TRIM('📥 Respostas'!AL203),'⚙️ Config'!$A$4:$B$13,2,0),"") | AJ203: =IFERROR(VLOOKUP(TRIM('📥 Respostas'!AM203),'⚙️ Config'!$A$4:$B$13,2,0),"") | AK203: =IFERROR(VLOOKUP(TRIM('📥 Respostas'!AN203),'⚙️ Config'!$A$4:$B$13,2,0),"") | AL203: =IFERROR(VLOOKUP(TRIM('📥 Respostas'!AO203),'⚙️ Config'!$A$4:$B$13,2,0),"") | AM203: =IFERROR(VLOOKUP(TRIM('📥 Respostas'!AP203),'⚙️ Config'!$A$4:$B$13,2,0),"") | AN203: =IFERROR(VLOOKUP(TRIM('📥 Respostas'!AQ203),'⚙️ Config'!$A$4:$B$13,2,0),"") | ... AR203: =IFERROR(VLOOKUP(TRIM('📥 Respostas'!AU203),'⚙️ Config'!$A$4:$B$13,2,0),"")

Sheet 📊 Risco por Setor
A1: 📊 AVALIAÇÃO DE RISCO PSICOSSOCIAL POR SETOR
A2: Calculado automaticamente. Classificação: Baixo (<25%) | Moderado (25–49%) | Alto (50–74%) | Crítico (≥75%)
A4: ▶ SETORES DA EMPRESA | C4: ← Preencha os setores existentes
A5: Operacional
A6: Administrativo / Técnico
A13: 📋 RESULTADOS POR FATOR E SETOR
A14: Setor | B14: Fator de Risco | C14: Nº Respondentes | D14: Score Médio (1–5) | E14: Risco (%) | F14: Classificação | G14: 🔴 Crítico | H14: 🟠 Alto | I14: ⚠️ Moderado
A15: =$A$5 -> Operacional | B15: Exigência Laboral | C15: =COUNTIF('🔢 Cálculo'!$B$4:$B$203,$A$5) -> 0 | D15: =IFERROR((IFERROR(AVERAGEIF('🔢 Cálculo'!$B$4:$B$203,$A$5,'🔢 Cálculo'!$D$4:$D$203),0)+IFERROR(AVERAGEIF('🔢 Cálculo'!$B$4:$B$203,$A$5,'🔢 Cálculo'!$E$4:$E$203),0)+IFERROR(AVERAGEIF('🔢 Cálculo'!$B$4:$B$203,$A$5,'🔢 Cálculo'!$F$4:$F$203),0)+IFERROR(AVERAGEIF('🔢 Cálculo'!$B$4:$B$203,$A$5,'🔢 Cálculo'!$G$4:$G$203),0)+IFERROR(AVERAGEIF('🔢 Cálculo'!$B$4:$B$203,$A$5,'🔢 Cálculo'!$H$4:$H$203),0)+IFERROR(AVERAGEIF('🔢 Cálculo'!$B$4:$B$203,$A$5,'🔢 Cálculo'!$I$4:$I$203),0))/6,"") -> 0 | E15: =IFERROR((IFERROR((AVERAGEIF('🔢 Cálculo'!$B$4:$B$203,$A$5,'🔢 Cálculo'!$D$4:$D$203)-1)/4*100,0)+IFERROR((AVERAGEIF('🔢 Cálculo'!$B$4:$B$203,$A$5,'🔢 Cálculo'!$E$4:$E$203)-1)/4*100,0)+IFERROR((AVERAGEIF('🔢 Cálculo'!$B$4:$B$203,$A$5,'🔢 Cálculo'!$F$4:$F$203)-1)/4*100,0)+IFERROR((AVERAGEIF('🔢 Cálculo'!$B$4:$B$203,$A$5,'🔢 Cálculo'!$G$4:$G$203)-1)/4*100,0)+IFERROR((AVERAGEIF('🔢 Cálculo'!$B$4:$B$203,$A$5,'🔢 Cálculo'!$H$4:$H$203)-1)/4*100,0)+IFERROR((AVERAGEIF('🔢 Cálculo'!$B$4:$B$203,$A$5,'🔢 Cálculo'!$I$4:$I$203)-1)/4*100,0))/6,"") -> 0 | F15: =IFERROR(IF(E15="","",IF(E15<25,"Baixo",IF(E15<50,"Moderado",IF(E15<75,"Alto","Crítico")))),"N/A") -> Baixo | G15: =IF(F15="Crítico","🔴 AÇÃO IMEDIATA","") | H15: =IF(F15="Alto","🟠 PRIORITÁRIO","") | I15: =IF(F15="Moderado","⚠️ PLANEJAR","")
A16: =$A$5 -> Operacional | B16: Organização do Trabalho | C16: =COUNTIF('🔢 Cálculo'!$B$4:$B$203,$A$5) -> 0 | D16: =IFERROR((IFERROR(AVERAGEIF('🔢 Cálculo'!$B$4:$B$203,$A$5,'🔢 Cálculo'!$J$4:$J$203),0)+IFERROR(AVERAGEIF('🔢 Cálculo'!$B$4:$B$203,$A$5,'🔢 Cálculo'!$K$4:$K$203),0)+IFERROR(AVERAGEIF('🔢 Cálculo'!$B$4:$B$203,$A$5,'🔢 Cálculo'!$L$4:$L$203),0)+IFERROR(AVERAGEIF('🔢 Cálculo'!$B$4:$B$203,$A$5,'🔢 Cálculo'!$M$4:$M$203),0)+IFERROR(AVERAGEIF('🔢 Cálculo'!$B$4:$B$203,$A$5,'🔢 Cálculo'!$N$4:$N$203),0)+IFERROR(AVERAGEIF('🔢 Cálculo'!$B$4:$B$203,$A$5,'🔢 Cálculo'!$O$4:$O$203),0))/6,"") -> 0 | E16: =IFERROR((IFERROR((5-AVERAGEIF('🔢 Cálculo'!$B$4:$B$203,$A$5,'🔢 Cálculo'!$J$4:$J$203))/4*100,0)+IFERROR((5-AVERAGEIF('🔢 Cálculo'!$B$4:$B$203,$A$5,'🔢 Cálculo'!$K$4:$K$203))/4*100,0)+IFERROR((5-AVERAGEIF('🔢 Cálculo'!$B$4:$B$203,$A$5,'🔢 Cálculo'!$L$4:$L$203))/4*100,0)+IFERROR((5-AVERAGEIF('🔢 Cálculo'!$B$4:$B$203,$A$5,'🔢 Cálculo'!$M$4:$M$203))/4*100,0)+IFERROR((5-AVERAGEIF('🔢 Cálculo'!$B$4:$B$203,$A$5,'🔢 Cálculo'!$N$4:$N$203))/4*100,0)+IFERROR((5-AVERAGEIF('🔢 Cálculo'!$B$4:$B$203,$A$5,'🔢 Cálculo'!$O$4:$O$203))/4*100,0))/6,"") -> 0 | F16: =IFERROR(IF(E16="","",IF(E16<25,"Baixo",IF(E16<50,"Moderado",IF(E16<75,"Alto","Crítico")))),"N/A") -> Baixo | G16: =IF(F16="Crítico","🔴 AÇÃO IMEDIATA","") | H16: =IF(F16="Alto","🟠 PRIORITÁRIO","") | I16: =IF(F16="Moderado","⚠️ PLANEJAR","")
A17: =$A$5 -> Operacional | B17: Relações Sociais e Liderança | C17: =COUNTIF('🔢 Cálculo'!$B$4:$B$203,$A$5) -> 0 | D17: =IFERROR((IFERROR(AVERAGEIF('🔢 Cálculo'!$B$4:$B$203,$A$5,'🔢 Cálculo'!$P$4:$P$203),0)+IFERROR(AVERAGEIF('🔢 Cálculo'!$B$4:$B$203,$A$5,'🔢 Cálculo'!$Q$4:$Q$203),0)+IFERROR(AVERAGEIF('🔢 Cálculo'!$B$4:$B$203,$A$5,'🔢 Cálculo'!$R$4:$R$203),0)+IFERROR(AVERAGEIF('🔢 Cálculo'!$B$4:$B$203,$A$5,'🔢 Cálculo'!$S$4:$S$203),0)+IFERROR(AVERAGEIF('🔢 Cálculo'!$B$4:$B$203,$A$5,'🔢 Cálculo'!$T$4:$T$203),0)+IFERROR(AVERAGEIF('🔢 Cálculo'!$B$4:$B$203,$A$5,'🔢 Cálculo'!$U$4:$U$203),0))/6,"") -> 0 | E17: =IFERROR((IFERROR((5-AVERAGEIF('🔢 Cálculo'!$B$4:$B$203,$A$5,'🔢 Cálculo'!$P$4:$P$203))/4*100,0)+IFERROR((5-AVERAGEIF('🔢 Cálculo'!$B$4:$B$203,$A$5,'🔢 Cálculo'!$Q$4:$Q$203))/4*100,0)+IFERROR((5-AVERAGEIF('🔢 Cálculo'!$B$4:$B$203,$A$5,'🔢 Cálculo'!$R$4:$R$203))/4*100,0)+IFERROR((5-AVERAGEIF('🔢 Cálculo'!$B$4:$B$203,$A$5,'🔢 Cálculo'!$S$4:$S$203))/4*100,0)+IFERROR((5-AVERAGEIF('🔢 Cálculo'!$B$4:$B$203,$A$5,'🔢 Cálculo'!$T$4:$T$203))/4*100,0)+IFERROR((5-AVERAGEIF('🔢 Cálculo'!$B$4:$B$203,$A$5,'🔢 Cálculo'!$U$4:$U$203))/4*100,0))/6,"") -> 0 | F17: =IFERROR(IF(E17="","",IF(E17<25,"Baixo",IF(E17<50,"Moderado",IF(E17<75,"Alto","Crítico")))),"N/A") -> Baixo | G17: =IF(F17="Crítico","🔴 AÇÃO IMEDIATA","") | H17: =IF(F17="Alto","🟠 PRIORITÁRIO","") | I17: =IF(F17="Moderado","⚠️ PLANEJAR","")
A18: =$A$5 -> Operacional | B18: Personalidade / Valores | C18: =COUNTIF('🔢 Cálculo'!$B$4:$B$203,$A$5) -> 0 | D18: =IFERROR((IFERROR(AVERAGEIF('🔢 Cálculo'!$B$4:$B$203,$A$5,'🔢 Cálculo'!$V$4:$V$203),0)+IFERROR(AVERAGEIF('🔢 Cálculo'!$B$4:$B$203,$A$5,'🔢 Cálculo'!$W$4:$W$203),0)+IFERROR(AVERAGEIF('🔢 Cálculo'!$B$4:$B$203,$A$5,'🔢 Cálculo'!$X$4:$X$203),0)+IFERROR(AVERAGEIF('🔢 Cálculo'!$B$4:$B$203,$A$5,'🔢 Cálculo'!$Y$4:$Y$203),0)+IFERROR(AVERAGEIF('🔢 Cálculo'!$B$4:$B$203,$A$5,'🔢 Cálculo'!$Z$4:$Z$203),0))/5,"") -> 0 | E18: =IFERROR((IFERROR((5-AVERAGEIF('🔢 Cálculo'!$B$4:$B$203,$A$5,'🔢 Cálculo'!$V$4:$V$203))/4*100,0)+IFERROR((5-AVERAGEIF('🔢 Cálculo'!$B$4:$B$203,$A$5,'🔢 Cálculo'!$W$4:$W$203))/4*100,0)+IFERROR((5-AVERAGEIF('🔢 Cálculo'!$B$4:$B$203,$A$5,'🔢 Cálculo'!$X$4:$X$203))/4*100,0)+IFERROR((5-AVERAGEIF('🔢 Cálculo'!$B$4:$B$203,$A$5,'🔢 Cálculo'!$Y$4:$Y$203))/4*100,0)+IFERROR((5-AVERAGEIF('🔢 Cálculo'!$B$4:$B$203,$A$5,'🔢 Cálculo'!$Z$4:$Z$203))/4*100,0))/5,"") -> 0 | F18: =IFERROR(IF(E18="","",IF(E18<25,"Baixo",IF(E18<50,"Moderado",IF(E18<75,"Alto","Crítico")))),"N/A") -> Baixo | G18: =IF(F18="Crítico","🔴 AÇÃO IMEDIATA","") | H18: =IF(F18="Alto","🟠 PRIORITÁRIO","") | I18: =IF(F18="Moderado","⚠️ PLANEJAR","")
A19: =$A$5 -> Operacional | B19: Interface Indivíduo-Trabalho | C19: =COUNTIF('🔢 Cálculo'!$B$4:$B$203,$A$5) -> 0 | D19: =IFERROR((IFERROR(AVERAGEIF('🔢 Cálculo'!$B$4:$B$203,$A$5,'🔢 Cálculo'!$AA$4:$AA$203),0)+IFERROR(AVERAGEIF('🔢 Cálculo'!$B$4:$B$203,$A$5,'🔢 Cálculo'!$AB$4:$AB$203),0)+IFERROR(AVERAGEIF('🔢 Cálculo'!$B$4:$B$203,$A$5,'🔢 Cálculo'!$AC$4:$AC$203),0)+IFERROR(AVERAGEIF('🔢 Cálculo'!$B$4:$B$203,$A$5,'🔢 Cálculo'!$AD$4:$AD$203),0)+IFERROR(AVERAGEIF('🔢 Cálculo'!$B$4:$B$203,$A$5,'🔢 Cálculo'!$AE$4:$AE$203),0))/5,"") -> 0 | E19: =IFERROR((IFERROR((5-AVERAGEIF('🔢 Cálculo'!$B$4:$B$203,$A$5,'🔢 Cálculo'!$AA$4:$AA$203))/4*100,0)+IFERROR((5-AVERAGEIF('🔢 Cálculo'!$B$4:$B$203,$A$5,'🔢 Cálculo'!$AB$4:$AB$203))/4*100,0)+IFERROR((5-AVERAGEIF('🔢 Cálculo'!$B$4:$B$203,$A$5,'🔢 Cálculo'!$AC$4:$AC$203))/4*100,0)+IFERROR((5-AVERAGEIF('🔢 Cálculo'!$B$4:$B$203,$A$5,'🔢 Cálculo'!$AD$4:$AD$203))/4*100,0)+IFERROR((AVERAGEIF('🔢 Cálculo'!$B$4:$B$203,$A$5,'🔢 Cálculo'!$AE$4:$AE$203)-1)/4*100,0))/5,"") -> 0 | F19: =IFERROR(IF(E19="","",IF(E19<25,"Baixo",IF(E19<50,"Moderado",IF(E19<75,"Alto","Crítico")))),"N/A") -> Baixo | G19: =IF(F19="Crítico","🔴 AÇÃO IMEDIATA","") | H19: =IF(F19="Alto","🟠 PRIORITÁRIO","") | I19: =IF(F19="Moderado","⚠️ PLANEJAR","")
A20: =$A$5 -> Operacional | B20: Saúde e Bem-Estar | C20: =COUNTIF('🔢 Cálculo'!$B$4:$B$203,$A$5) -> 0 | D20: =IFERROR((IFERROR(AVERAGEIF('🔢 Cálculo'!$B$4:$B$203,$A$5,'🔢 Cálculo'!$AF$4:$AF$203),0)+IFERROR(AVERAGEIF('🔢 Cálculo'!$B$4:$B$203,$A$5,'🔢 Cálculo'!$AG$4:$AG$203),0)+IFERROR(AVERAGEIF('🔢 Cálculo'!$B$4:$B$203,$A$5,'🔢 Cálculo'!$AH$4:$AH$203),0)+IFERROR(AVERAGEIF('🔢 Cálculo'!$B$4:$B$203,$A$5,'🔢 Cálculo'!$AI$4:$AI$203),0)+IFERROR(AVERAGEIF('🔢 Cálculo'!$B$4:$B$203,$A$5,'🔢 Cálculo'!$AJ$4:$AJ$203),0)+IFERROR(AVERAGEIF('🔢 Cálculo'!$B$4:$B$203,$A$5,'🔢 Cálculo'!$AK$4:$AK$203),0)+IFERROR(AVERAGEIF('🔢 Cálculo'!$B$4:$B$203,$A$5,'🔢 Cálculo'!$AL$4:$AL$203),0)+IFERROR(AVERAGEIF('🔢 Cálculo'!$B$4:$B$203,$A$5,'🔢 Cálculo'!$AM$4:$AM$203),0)+IFERROR(AVERAGEIF('🔢 Cálculo'!$B$4:$B$203,$A$5,'🔢 Cálculo'!$AN$4:$AN$203),0))/9,"") -> 0 | E20: =IFERROR((IFERROR((5-AVERAGEIF('🔢 Cálculo'!$B$4:$B$203,$A$5,'🔢 Cálculo'!$AF$4:$AF$203))/4*100,0)+IFERROR((AVERAGEIF('🔢 Cálculo'!$B$4:$B$203,$A$5,'🔢 Cálculo'!$AG$4:$AG$203)-1)/4*100,0)+IFERROR((AVERAGEIF('🔢 Cálculo'!$B$4:$B$203,$A$5,'🔢 Cálculo'!$AH$4:$AH$203)-1)/4*100,0)+IFERROR((AVERAGEIF('🔢 Cálculo'!$B$4:$B$203,$A$5,'🔢 Cálculo'!$AI$4:$AI$203)-1)/4*100,0)+IFERROR((AVERAGEIF('🔢 Cálculo'!$B$4:$B$203,$A$5,'🔢 Cálculo'!$AJ$4:$AJ$203)-1)/4*100,0)+IFERROR((AVERAGEIF('🔢 Cálculo'!$B$4:$B$203,$A$5,'🔢 Cálculo'!$AK$4:$AK$203)-1)/4*100,0)+IFERROR((AVERAGEIF('🔢 Cálculo'!$B$4:$B$203,$A$5,'🔢 Cálculo'!$AL$4:$AL$203)-1)/4*100,0)+IFERROR((AVERAGEIF('🔢 Cálculo'!$B$4:$B$203,$A$5,'🔢 Cálculo'!$AM$4:$AM$203)-1)/4*100,0)+IFERROR((AVERAGEIF('🔢 Cálculo'!$B$4:$B$203,$A$5,'🔢 Cálculo'!$AN$4:$AN$203)-1)/4*100,0))/9,"") -> 0 | F20: =IFERROR(IF(E20="","",IF(E20<25,"Baixo",IF(E20<50,"Moderado",IF(E20<75,"Alto","Crítico")))),"N/A") -> Baixo | G20: =IF(F20="Crítico","🔴 AÇÃO IMEDIATA","") | H20: =IF(F20="Alto","🟠 PRIORITÁRIO","") | I20: =IF(F20="Moderado","⚠️ PLANEJAR","")
A21: =$A$5 -> Operacional | B21: Comportamentos Ofensivos | C21: =COUNTIF('🔢 Cálculo'!$B$4:$B$203,$A$5) -> 0 | D21: =IFERROR((IFERROR(AVERAGEIF('🔢 Cálculo'!$B$4:$B$203,$A$5,'🔢 Cálculo'!$AO$4:$AO$203),0)+IFERROR(AVERAGEIF('🔢 Cálculo'!$B$4:$B$203,$A$5,'🔢 Cálculo'!$AP$4:$AP$203),0)+IFERROR(AVERAGEIF('🔢 Cálculo'!$B$4:$B$203,$A$5,'🔢 Cálculo'!$AQ$4:$AQ$203),0)+IFERROR(AVERAGEIF('🔢 Cálculo'!$B$4:$B$203,$A$5,'🔢 Cálculo'!$AR$4:$AR$203),0))/4,"") -> 0 | E21: =IFERROR((IFERROR((AVERAGEIF('🔢 Cálculo'!$B$4:$B$203,$A$5,'🔢 Cálculo'!$AO$4:$AO$203)-1)/4*100,0)+IFERROR((AVERAGEIF('🔢 Cálculo'!$B$4:$B$203,$A$5,'🔢 Cálculo'!$AP$4:$AP$203)-1)/4*100,0)+IFERROR((AVERAGEIF('🔢 Cálculo'!$B$4:$B$203,$A$5,'🔢 Cálculo'!$AQ$4:$AQ$203)-1)/4*100,0)+IFERROR((AVERAGEIF('🔢 Cálculo'!$B$4:$B$203,$A$5,'🔢 Cálculo'!$AR$4:$AR$203)-1)/4*100,0))/4,"") -> 0 | F21: =IFERROR(IF(E21="","",IF(E21<25,"Baixo",IF(E21<50,"Moderado",IF(E21<75,"Alto","Crítico")))),"N/A") -> Baixo | G21: =IF(F21="Crítico","🔴 AÇÃO IMEDIATA","") | H21: =IF(F21="Alto","🟠 PRIORITÁRIO","") | I21: =IF(F21="Moderado","⚠️ PLANEJAR","")
A22: =$A$6 -> Administrativo / Técnico | B22: Exigência Laboral | C22: =COUNTIF('🔢 Cálculo'!$B$4:$B$203,$A$6) -> 0 | D22: =IFERROR((IFERROR(AVERAGEIF('🔢 Cálculo'!$B$4:$B$203,$A$6,'🔢 Cálculo'!$D$4:$D$203),0)+IFERROR(AVERAGEIF('🔢 Cálculo'!$B$4:$B$203,$A$6,'🔢 Cálculo'!$E$4:$E$203),0)+IFERROR(AVERAGEIF('🔢 Cálculo'!$B$4:$B$203,$A$6,'🔢 Cálculo'!$F$4:$F$203),0)+IFERROR(AVERAGEIF('🔢 Cálculo'!$B$4:$B$203,$A$6,'🔢 Cálculo'!$G$4:$G$203),0)+IFERROR(AVERAGEIF('🔢 Cálculo'!$B$4:$B$203,$A$6,'🔢 Cálculo'!$H$4:$H$203),0)+IFERROR(AVERAGEIF('🔢 Cálculo'!$B$4:$B$203,$A$6,'🔢 Cálculo'!$I$4:$I$203),0))/6,"") -> 0 | E22: =IFERROR((IFERROR((AVERAGEIF('🔢 Cálculo'!$B$4:$B$203,$A$6,'🔢 Cálculo'!$D$4:$D$203)-1)/4*100,0)+IFERROR((AVERAGEIF('🔢 Cálculo'!$B$4:$B$203,$A$6,'🔢 Cálculo'!$E$4:$E$203)-1)/4*100,0)+IFERROR((AVERAGEIF('🔢 Cálculo'!$B$4:$B$203,$A$6,'🔢 Cálculo'!$F$4:$F$203)-1)/4*100,0)+IFERROR((AVERAGEIF('🔢 Cálculo'!$B$4:$B$203,$A$6,'🔢 Cálculo'!$G$4:$G$203)-1)/4*100,0)+IFERROR((AVERAGEIF('🔢 Cálculo'!$B$4:$B$203,$A$6,'🔢 Cálculo'!$H$4:$H$203)-1)/4*100,0)+IFERROR((AVERAGEIF('🔢 Cálculo'!$B$4:$B$203,$A$6,'🔢 Cálculo'!$I$4:$I$203)-1)/4*100,0))/6,"") -> 0 | F22: =IFERROR(IF(E22="","",IF(E22<25,"Baixo",IF(E22<50,"Moderado",IF(E22<75,"Alto","Crítico")))),"N/A") -> Baixo | G22: =IF(F22="Crítico","🔴 AÇÃO IMEDIATA","") | H22: =IF(F22="Alto","🟠 PRIORITÁRIO","") | I22: =IF(F22="Moderado","⚠️ PLANEJAR","")
A23: =$A$6 -> Administrativo / Técnico | B23: Organização do Trabalho | C23: =COUNTIF('🔢 Cálculo'!$B$4:$B$203,$A$6) -> 0 | D23: =IFERROR((IFERROR(AVERAGEIF('🔢 Cálculo'!$B$4:$B$203,$A$6,'🔢 Cálculo'!$J$4:$J$203),0)+IFERROR(AVERAGEIF('🔢 Cálculo'!$B$4:$B$203,$A$6,'🔢 Cálculo'!$K$4:$K$203),0)+IFERROR(AVERAGEIF('🔢 Cálculo'!$B$4:$B$203,$A$6,'🔢 Cálculo'!$L$4:$L$203),0)+IFERROR(AVERAGEIF('🔢 Cálculo'!$B$4:$B$203,$A$6,'🔢 Cálculo'!$M$4:$M$203),0)+IFERROR(AVERAGEIF('🔢 Cálculo'!$B$4:$B$203,$A$6,'🔢 Cálculo'!$N$4:$N$203),0)+IFERROR(AVERAGEIF('🔢 Cálculo'!$B$4:$B$203,$A$6,'🔢 Cálculo'!$O$4:$O$203),0))/6,"") -> 0 | E23: =IFERROR((IFERROR((5-AVERAGEIF('🔢 Cálculo'!$B$4:$B$203,$A$6,'🔢 Cálculo'!$J$4:$J$203))/4*100,0)+IFERROR((5-AVERAGEIF('🔢 Cálculo'!$B$4:$B$203,$A$6,'🔢 Cálculo'!$K$4:$K$203))/4*100,0)+IFERROR((5-AVERAGEIF('🔢 Cálculo'!$B$4:$B$203,$A$6,'🔢 Cálculo'!$L$4:$L$203))/4*100,0)+IFERROR((5-AVERAGEIF('🔢 Cálculo'!$B$4:$B$203,$A$6,'🔢 Cálculo'!$M$4:$M$203))/4*100,0)+IFERROR((5-AVERAGEIF('🔢 Cálculo'!$B$4:$B$203,$A$6,'🔢 Cálculo'!$N$4:$N$203))/4*100,0)+IFERROR((5-AVERAGEIF('🔢 Cálculo'!$B$4:$B$203,$A$6,'🔢 Cálculo'!$O$4:$O$203))/4*100,0))/6,"") -> 0 | F23: =IFERROR(IF(E23="","",IF(E23<25,"Baixo",IF(E23<50,"Moderado",IF(E23<75,"Alto","Crítico")))),"N/A") -> Baixo | G23: =IF(F23="Crítico","🔴 AÇÃO IMEDIATA","") | H23: =IF(F23="Alto","🟠 PRIORITÁRIO","") | I23: =IF(F23="Moderado","⚠️ PLANEJAR","")
A24: =$A$6 -> Administrativo / Técnico | B24: Relações Sociais e Liderança | C24: =COUNTIF('🔢 Cálculo'!$B$4:$B$203,$A$6) -> 0 | D24: =IFERROR((IFERROR(AVERAGEIF('🔢 Cálculo'!$B$4:$B$203,$A$6,'🔢 Cálculo'!$P$4:$P$203),0)+IFERROR(AVERAGEIF('🔢 Cálculo'!$B$4:$B$203,$A$6,'🔢 Cálculo'!$Q$4:$Q$203),0)+IFERROR(AVERAGEIF('🔢 Cálculo'!$B$4:$B$203,$A$6,'🔢 Cálculo'!$R$4:$R$203),0)+IFERROR(AVERAGEIF('🔢 Cálculo'!$B$4:$B$203,$A$6,'🔢 Cálculo'!$S$4:$S$203),0)+IFERROR(AVERAGEIF('🔢 Cálculo'!$B$4:$B$203,$A$6,'🔢 Cálculo'!$T$4:$T$203),0)+IFERROR(AVERAGEIF('🔢 Cálculo'!$B$4:$B$203,$A$6,'🔢 Cálculo'!$U$4:$U$203),0))/6,"") -> 0 | E24: =IFERROR((IFERROR((5-AVERAGEIF('🔢 Cálculo'!$B$4:$B$203,$A$6,'🔢 Cálculo'!$P$4:$P$203))/4*100,0)+IFERROR((5-AVERAGEIF('🔢 Cálculo'!$B$4:$B$203,$A$6,'🔢 Cálculo'!$Q$4:$Q$203))/4*100,0)+IFERROR((5-AVERAGEIF('🔢 Cálculo'!$B$4:$B$203,$A$6,'🔢 Cálculo'!$R$4:$R$203))/4*100,0)+IFERROR((5-AVERAGEIF('🔢 Cálculo'!$B$4:$B$203,$A$6,'🔢 Cálculo'!$S$4:$S$203))/4*100,0)+IFERROR((5-AVERAGEIF('🔢 Cálculo'!$B$4:$B$203,$A$6,'🔢 Cálculo'!$T$4:$T$203))/4*100,0)+IFERROR((5-AVERAGEIF('🔢 Cálculo'!$B$4:$B$203,$A$6,'🔢 Cálculo'!$U$4:$U$203))/4*100,0))/6,"") -> 0 | F24: =IFERROR(IF(E24="","",IF(E24<25,"Baixo",IF(E24<50,"Moderado",IF(E24<75,"Alto","Crítico")))),"N/A") -> Baixo | G24: =IF(F24="Crítico","🔴 AÇÃO IMEDIATA","") | H24: =IF(F24="Alto","🟠 PRIORITÁRIO","") | I24: =IF(F24="Moderado","⚠️ PLANEJAR","")
A25: =$A$6 -> Administrativo / Técnico | B25: Personalidade / Valores | C25: =COUNTIF('🔢 Cálculo'!$B$4:$B$203,$A$6) -> 0 | D25: =IFERROR((IFERROR(AVERAGEIF('🔢 Cálculo'!$B$4:$B$203,$A$6,'🔢 Cálculo'!$V$4:$V$203),0)+IFERROR(AVERAGEIF('🔢 Cálculo'!$B$4:$B$203,$A$6,'🔢 Cálculo'!$W$4:$W$203),0)+IFERROR(AVERAGEIF('🔢 Cálculo'!$B$4:$B$203,$A$6,'🔢 Cálculo'!$X$4:$X$203),0)+IFERROR(AVERAGEIF('🔢 Cálculo'!$B$4:$B$203,$A$6,'🔢 Cálculo'!$Y$4:$Y$203),0)+IFERROR(AVERAGEIF('🔢 Cálculo'!$B$4:$B$203,$A$6,'🔢 Cálculo'!$Z$4:$Z$203),0))/5,"") -> 0 | E25: =IFERROR((IFERROR((5-AVERAGEIF('🔢 Cálculo'!$B$4:$B$203,$A$6,'🔢 Cálculo'!$V$4:$V$203))/4*100,0)+IFERROR((5-AVERAGEIF('🔢 Cálculo'!$B$4:$B$203,$A$6,'🔢 Cálculo'!$W$4:$W$203))/4*100,0)+IFERROR((5-AVERAGEIF('🔢 Cálculo'!$B$4:$B$203,$A$6,'🔢 Cálculo'!$X$4:$X$203))/4*100,0)+IFERROR((5-AVERAGEIF('🔢 Cálculo'!$B$4:$B$203,$A$6,'🔢 Cálculo'!$Y$4:$Y$203))/4*100,0)+IFERROR((5-AVERAGEIF('🔢 Cálculo'!$B$4:$B$203,$A$6,'🔢 Cálculo'!$Z$4:$Z$203))/4*100,0))/5,"") -> 0 | F25: =IFERROR(IF(E25="","",IF(E25<25,"Baixo",IF(E25<50,"Moderado",IF(E25<75,"Alto","Crítico")))),"N/A") -> Baixo | G25: =IF(F25="Crítico","🔴 AÇÃO IMEDIATA","") | H25: =IF(F25="Alto","🟠 PRIORITÁRIO","") | I25: =IF(F25="Moderado","⚠️ PLANEJAR","")
A26: =$A$6 -> Administrativo / Técnico | B26: Interface Indivíduo-Trabalho | C26: =COUNTIF('🔢 Cálculo'!$B$4:$B$203,$A$6) -> 0 | D26: =IFERROR((IFERROR(AVERAGEIF('🔢 Cálculo'!$B$4:$B$203,$A$6,'🔢 Cálculo'!$AA$4:$AA$203),0)+IFERROR(AVERAGEIF('🔢 Cálculo'!$B$4:$B$203,$A$6,'🔢 Cálculo'!$AB$4:$AB$203),0)+IFERROR(AVERAGEIF('🔢 Cálculo'!$B$4:$B$203,$A$6,'🔢 Cálculo'!$AC$4:$AC$203),0)+IFERROR(AVERAGEIF('🔢 Cálculo'!$B$4:$B$203,$A$6,'🔢 Cálculo'!$AD$4:$AD$203),0)+IFERROR(AVERAGEIF('🔢 Cálculo'!$B$4:$B$203,$A$6,'🔢 Cálculo'!$AE$4:$AE$203),0))/5,"") -> 0 | E26: =IFERROR((IFERROR((5-AVERAGEIF('🔢 Cálculo'!$B$4:$B$203,$A$6,'🔢 Cálculo'!$AA$4:$AA$203))/4*100,0)+IFERROR((5-AVERAGEIF('🔢 Cálculo'!$B$4:$B$203,$A$6,'🔢 Cálculo'!$AB$4:$AB$203))/4*100,0)+IFERROR((5-AVERAGEIF('🔢 Cálculo'!$B$4:$B$203,$A$6,'🔢 Cálculo'!$AC$4:$AC$203))/4*100,0)+IFERROR((5-AVERAGEIF('🔢 Cálculo'!$B$4:$B$203,$A$6,'🔢 Cálculo'!$AD$4:$AD$203))/4*100,0)+IFERROR((AVERAGEIF('🔢 Cálculo'!$B$4:$B$203,$A$6,'🔢 Cálculo'!$AE$4:$AE$203)-1)/4*100,0))/5,"") -> 0 | F26: =IFERROR(IF(E26="","",IF(E26<25,"Baixo",IF(E26<50,"Moderado",IF(E26<75,"Alto","Crítico")))),"N/A") -> Baixo | G26: =IF(F26="Crítico","🔴 AÇÃO IMEDIATA","") | H26: =IF(F26="Alto","🟠 PRIORITÁRIO","") | I26: =IF(F26="Moderado","⚠️ PLANEJAR","")
A27: =$A$6 -> Administrativo / Técnico | B27: Saúde e Bem-Estar | C27: =COUNTIF('🔢 Cálculo'!$B$4:$B$203,$A$6) -> 0 | D27: =IFERROR((IFERROR(AVERAGEIF('🔢 Cálculo'!$B$4:$B$203,$A$6,'🔢 Cálculo'!$AF$4:$AF$203),0)+IFERROR(AVERAGEIF('🔢 Cálculo'!$B$4:$B$203,$A$6,'🔢 Cálculo'!$AG$4:$AG$203),0)+IFERROR(AVERAGEIF('🔢 Cálculo'!$B$4:$B$203,$A$6,'🔢 Cálculo'!$AH$4:$AH$203),0)+IFERROR(AVERAGEIF('🔢 Cálculo'!$B$4:$B$203,$A$6,'🔢 Cálculo'!$AI$4:$AI$203),0)+IFERROR(AVERAGEIF('🔢 Cálculo'!$B$4:$B$203,$A$6,'🔢 Cálculo'!$AJ$4:$AJ$203),0)+IFERROR(AVERAGEIF('🔢 Cálculo'!$B$4:$B$203,$A$6,'🔢 Cálculo'!$AK$4:$AK$203),0)+IFERROR(AVERAGEIF('🔢 Cálculo'!$B$4:$B$203,$A$6,'🔢 Cálculo'!$AL$4:$AL$203),0)+IFERROR(AVERAGEIF('🔢 Cálculo'!$B$4:$B$203,$A$6,'🔢 Cálculo'!$AM$4:$AM$203),0)+IFERROR(AVERAGEIF('🔢 Cálculo'!$B$4:$B$203,$A$6,'🔢 Cálculo'!$AN$4:$AN$203),0))/9,"") -> 0 | E27: =IFERROR((IFERROR((5-AVERAGEIF('🔢 Cálculo'!$B$4:$B$203,$A$6,'🔢 Cálculo'!$AF$4:$AF$203))/4*100,0)+IFERROR((AVERAGEIF('🔢 Cálculo'!$B$4:$B$203,$A$6,'🔢 Cálculo'!$AG$4:$AG$203)-1)/4*100,0)+IFERROR((AVERAGEIF('🔢 Cálculo'!$B$4:$B$203,$A$6,'🔢 Cálculo'!$AH$4:$AH$203)-1)/4*100,0)+IFERROR((AVERAGEIF('🔢 Cálculo'!$B$4:$B$203,$A$6,'🔢 Cálculo'!$AI$4:$AI$203)-1)/4*100,0)+IFERROR((AVERAGEIF('🔢 Cálculo'!$B$4:$B$203,$A$6,'🔢 Cálculo'!$AJ$4:$AJ$203)-1)/4*100,0)+IFERROR((AVERAGEIF('🔢 Cálculo'!$B$4:$B$203,$A$6,'🔢 Cálculo'!$AK$4:$AK$203)-1)/4*100,0)+IFERROR((AVERAGEIF('🔢 Cálculo'!$B$4:$B$203,$A$6,'🔢 Cálculo'!$AL$4:$AL$203)-1)/4*100,0)+IFERROR((AVERAGEIF('🔢 Cálculo'!$B$4:$B$203,$A$6,'🔢 Cálculo'!$AM$4:$AM$203)-1)/4*100,0)+IFERROR((AVERAGEIF('🔢 Cálculo'!$B$4:$B$203,$A$6,'🔢 Cálculo'!$AN$4:$AN$203)-1)/4*100,0))/9,"") -> 0 | F27: =IFERROR(IF(E27="","",IF(E27<25,"Baixo",IF(E27<50,"Moderado",IF(E27<75,"Alto","Crítico")))),"N/A") -> Baixo | G27: =IF(F27="Crítico","🔴 AÇÃO IMEDIATA","") | H27: =IF(F27="Alto","🟠 PRIORITÁRIO","") | I27: =IF(F27="Moderado","⚠️ PLANEJAR","")
A28: =$A$6 -> Administrativo / Técnico | B28: Comportamentos Ofensivos | C28: =COUNTIF('🔢 Cálculo'!$B$4:$B$203,$A$6) -> 0 | D28: =IFERROR((IFERROR(AVERAGEIF('🔢 Cálculo'!$B$4:$B$203,$A$6,'🔢 Cálculo'!$AO$4:$AO$203),0)+IFERROR(AVERAGEIF('🔢 Cálculo'!$B$4:$B$203,$A$6,'🔢 Cálculo'!$AP$4:$AP$203),0)+IFERROR(AVERAGEIF('🔢 Cálculo'!$B$4:$B$203,$A$6,'🔢 Cálculo'!$AQ$4:$AQ$203),0)+IFERROR(AVERAGEIF('🔢 Cálculo'!$B$4:$B$203,$A$6,'🔢 Cálculo'!$AR$4:$AR$203),0))/4,"") -> 0 | E28: =IFERROR((IFERROR((AVERAGEIF('🔢 Cálculo'!$B$4:$B$203,$A$6,'🔢 Cálculo'!$AO$4:$AO$203)-1)/4*100,0)+IFERROR((AVERAGEIF('🔢 Cálculo'!$B$4:$B$203,$A$6,'🔢 Cálculo'!$AP$4:$AP$203)-1)/4*100,0)+IFERROR((AVERAGEIF('🔢 Cálculo'!$B$4:$B$203,$A$6,'🔢 Cálculo'!$AQ$4:$AQ$203)-1)/4*100,0)+IFERROR((AVERAGEIF('🔢 Cálculo'!$B$4:$B$203,$A$6,'🔢 Cálculo'!$AR$4:$AR$203)-1)/4*100,0))/4,"") -> 0 | F28: =IFERROR(IF(E28="","",IF(E28<25,"Baixo",IF(E28<50,"Moderado",IF(E28<75,"Alto","Crítico")))),"N/A") -> Baixo | G28: =IF(F28="Crítico","🔴 AÇÃO IMEDIATA","") | H28: =IF(F28="Alto","🟠 PRIORITÁRIO","") | I28: =IF(F28="Moderado","⚠️ PLANEJAR","")
A29: =$A$7 -> 0 | B29: Exigência Laboral | C29: =COUNTIF('🔢 Cálculo'!$B$4:$B$203,$A$7) -> 200 | D29: =IFERROR((IFERROR(AVERAGEIF('🔢 Cálculo'!$B$4:$B$203,$A$7,'🔢 Cálculo'!$D$4:$D$203),0)+IFERROR(AVERAGEIF('🔢 Cálculo'!$B$4:$B$203,$A$7,'🔢 Cálculo'!$E$4:$E$203),0)+IFERROR(AVERAGEIF('🔢 Cálculo'!$B$4:$B$203,$A$7,'🔢 Cálculo'!$F$4:$F$203),0)+IFERROR(AVERAGEIF('🔢 Cálculo'!$B$4:$B$203,$A$7,'🔢 Cálculo'!$G$4:$G$203),0)+IFERROR(AVERAGEIF('🔢 Cálculo'!$B$4:$B$203,$A$7,'🔢 Cálculo'!$H$4:$H$203),0)+IFERROR(AVERAGEIF('🔢 Cálculo'!$B$4:$B$203,$A$7,'🔢 Cálculo'!$I$4:$I$203),0))/6,"") -> 0 | E29: =IFERROR((IFERROR((AVERAGEIF('🔢 Cálculo'!$B$4:$B$203,$A$7,'🔢 Cálculo'!$D$4:$D$203)-1)/4*100,0)+IFERROR((AVERAGEIF('🔢 Cálculo'!$B$4:$B$203,$A$7,'🔢 Cálculo'!$E$4:$E$203)-1)/4*100,0)+IFERROR((AVERAGEIF('🔢 Cálculo'!$B$4:$B$203,$A$7,'🔢 Cálculo'!$F$4:$F$203)-1)/4*100,0)+IFERROR((AVERAGEIF('🔢 Cálculo'!$B$4:$B$203,$A$7,'🔢 Cálculo'!$G$4:$G$203)-1)/4*100,0)+IFERROR((AVERAGEIF('🔢 Cálculo'!$B$4:$B$203,$A$7,'🔢 Cálculo'!$H$4:$H$203)-1)/4*100,0)+IFERROR((AVERAGEIF('🔢 Cálculo'!$B$4:$B$203,$A$7,'🔢 Cálculo'!$I$4:$I$203)-1)/4*100,0))/6,"") -> 0 | F29: =IFERROR(IF(E29="","",IF(E29<25,"Baixo",IF(E29<50,"Moderado",IF(E29<75,"Alto","Crítico")))),"N/A") -> Baixo | G29: =IF(F29="Crítico","🔴 AÇÃO IMEDIATA","") | H29: =IF(F29="Alto","🟠 PRIORITÁRIO","") | I29: =IF(F29="Moderado","⚠️ PLANEJAR","")
A30: =$A$7 -> 0 | B30: Organização do Trabalho | C30: =COUNTIF('🔢 Cálculo'!$B$4:$B$203,$A$7) -> 200 | D30: =IFERROR((IFERROR(AVERAGEIF('🔢 Cálculo'!$B$4:$B$203,$A$7,'🔢 Cálculo'!$J$4:$J$203),0)+IFERROR(AVERAGEIF('🔢 Cálculo'!$B$4:$B$203,$A$7,'🔢 Cálculo'!$K$4:$K$203),0)+IFERROR(AVERAGEIF('🔢 Cálculo'!$B$4:$B$203,$A$7,'🔢 Cálculo'!$L$4:$L$203),0)+IFERROR(AVERAGEIF('🔢 Cálculo'!$B$4:$B$203,$A$7,'🔢 Cálculo'!$M$4:$M$203),0)+IFERROR(AVERAGEIF('🔢 Cálculo'!$B$4:$B$203,$A$7,'🔢 Cálculo'!$N$4:$N$203),0)+IFERROR(AVERAGEIF('🔢 Cálculo'!$B$4:$B$203,$A$7,'🔢 Cálculo'!$O$4:$O$203),0))/6,"") -> 0 | E30: =IFERROR((IFERROR((5-AVERAGEIF('🔢 Cálculo'!$B$4:$B$203,$A$7,'🔢 Cálculo'!$J$4:$J$203))/4*100,0)+IFERROR((5-AVERAGEIF('🔢 Cálculo'!$B$4:$B$203,$A$7,'🔢 Cálculo'!$K$4:$K$203))/4*100,0)+IFERROR((5-AVERAGEIF('🔢 Cálculo'!$B$4:$B$203,$A$7,'🔢 Cálculo'!$L$4:$L$203))/4*100,0)+IFERROR((5-AVERAGEIF('🔢 Cálculo'!$B$4:$B$203,$A$7,'🔢 Cálculo'!$M$4:$M$203))/4*100,0)+IFERROR((5-AVERAGEIF('🔢 Cálculo'!$B$4:$B$203,$A$7,'🔢 Cálculo'!$N$4:$N$203))/4*100,0)+IFERROR((5-AVERAGEIF('🔢 Cálculo'!$B$4:$B$203,$A$7,'🔢 Cálculo'!$O$4:$O$203))/4*100,0))/6,"") -> 0 | F30: =IFERROR(IF(E30="","",IF(E30<25,"Baixo",IF(E30<50,"Moderado",IF(E30<75,"Alto","Crítico")))),"N/A") -> Baixo | G30: =IF(F30="Crítico","🔴 AÇÃO IMEDIATA","") | H30: =IF(F30="Alto","🟠 PRIORITÁRIO","") | I30: =IF(F30="Moderado","⚠️ PLANEJAR","")
A31: =$A$7 -> 0 | B31: Relações Sociais e Liderança | C31: =COUNTIF('🔢 Cálculo'!$B$4:$B$203,$A$7) -> 200 | D31: =IFERROR((IFERROR(AVERAGEIF('🔢 Cálculo'!$B$4:$B$203,$A$7,'🔢 Cálculo'!$P$4:$P$203),0)+IFERROR(AVERAGEIF('🔢 Cálculo'!$B$4:$B$203,$A$7,'🔢 Cálculo'!$Q$4:$Q$203),0)+IFERROR(AVERAGEIF('🔢 Cálculo'!$B$4:$B$203,$A$7,'🔢 Cálculo'!$R$4:$R$203),0)+IFERROR(AVERAGEIF('🔢 Cálculo'!$B$4:$B$203,$A$7,'🔢 Cálculo'!$S$4:$S$203),0)+IFERROR(AVERAGEIF('🔢 Cálculo'!$B$4:$B$203,$A$7,'🔢 Cálculo'!$T$4:$T$203),0)+IFERROR(AVERAGEIF('🔢 Cálculo'!$B$4:$B$203,$A$7,'🔢 Cálculo'!$U$4:$U$203),0))/6,"") -> 0 | E31: =IFERROR((IFERROR((5-AVERAGEIF('🔢 Cálculo'!$B$4:$B$203,$A$7,'🔢 Cálculo'!$P$4:$P$203))/4*100,0)+IFERROR((5-AVERAGEIF('🔢 Cálculo'!$B$4:$B$203,$A$7,'🔢 Cálculo'!$Q$4:$Q$203))/4*100,0)+IFERROR((5-AVERAGEIF('🔢 Cálculo'!$B$4:$B$203,$A$7,'🔢 Cálculo'!$R$4:$R$203))/4*100,0)+IFERROR((5-AVERAGEIF('🔢 Cálculo'!$B$4:$B$203,$A$7,'🔢 Cálculo'!$S$4:$S$203))/4*100,0)+IFERROR((5-AVERAGEIF('🔢 Cálculo'!$B$4:$B$203,$A$7,'🔢 Cálculo'!$T$4:$T$203))/4*100,0)+IFERROR((5-AVERAGEIF('🔢 Cálculo'!$B$4:$B$203,$A$7,'🔢 Cálculo'!$U$4:$U$203))/4*100,0))/6,"") -> 0 | F31: =IFERROR(IF(E31="","",IF(E31<25,"Baixo",IF(E31<50,"Moderado",IF(E31<75,"Alto","Crítico")))),"N/A") -> Baixo | G31: =IF(F31="Crítico","🔴 AÇÃO IMEDIATA","") | H31: =IF(F31="Alto","🟠 PRIORITÁRIO","") | I31: =IF(F31="Moderado","⚠️ PLANEJAR","")
A32: =$A$7 -> 0 | B32: Personalidade / Valores | C32: =COUNTIF('🔢 Cálculo'!$B$4:$B$203,$A$7) -> 200 | D32: =IFERROR((IFERROR(AVERAGEIF('🔢 Cálculo'!$B$4:$B$203,$A$7,'🔢 Cálculo'!$V$4:$V$203),0)+IFERROR(AVERAGEIF('🔢 Cálculo'!$B$4:$B$203,$A$7,'🔢 Cálculo'!$W$4:$W$203),0)+IFERROR(AVERAGEIF('🔢 Cálculo'!$B$4:$B$203,$A$7,'🔢 Cálculo'!$X$4:$X$203),0)+IFERROR(AVERAGEIF('🔢 Cálculo'!$B$4:$B$203,$A$7,'🔢 Cálculo'!$Y$4:$Y$203),0)+IFERROR(AVERAGEIF('🔢 Cálculo'!$B$4:$B$203,$A$7,'🔢 Cálculo'!$Z$4:$Z$203),0))/5,"") -> 0 | E32: =IFERROR((IFERROR((5-AVERAGEIF('🔢 Cálculo'!$B$4:$B$203,$A$7,'🔢 Cálculo'!$V$4:$V$203))/4*100,0)+IFERROR((5-AVERAGEIF('🔢 Cálculo'!$B$4:$B$203,$A$7,'🔢 Cálculo'!$W$4:$W$203))/4*100,0)+IFERROR((5-AVERAGEIF('🔢 Cálculo'!$B$4:$B$203,$A$7,'🔢 Cálculo'!$X$4:$X$203))/4*100,0)+IFERROR((5-AVERAGEIF('🔢 Cálculo'!$B$4:$B$203,$A$7,'🔢 Cálculo'!$Y$4:$Y$203))/4*100,0)+IFERROR((5-AVERAGEIF('🔢 Cálculo'!$B$4:$B$203,$A$7,'🔢 Cálculo'!$Z$4:$Z$203))/4*100,0))/5,"") -> 0 | F32: =IFERROR(IF(E32="","",IF(E32<25,"Baixo",IF(E32<50,"Moderado",IF(E32<75,"Alto","Crítico")))),"N/A") -> Baixo | G32: =IF(F32="Crítico","🔴 AÇÃO IMEDIATA","") | H32: =IF(F32="Alto","🟠 PRIORITÁRIO","") | I32: =IF(F32="Moderado","⚠️ PLANEJAR","")
A33: =$A$7 -> 0 | B33: Interface Indivíduo-Trabalho | C33: =COUNTIF('🔢 Cálculo'!$B$4:$B$203,$A$7) -> 200 | D33: =IFERROR((IFERROR(AVERAGEIF('🔢 Cálculo'!$B$4:$B$203,$A$7,'🔢 Cálculo'!$AA$4:$AA$203),0)+IFERROR(AVERAGEIF('🔢 Cálculo'!$B$4:$B$203,$A$7,'🔢 Cálculo'!$AB$4:$AB$203),0)+IFERROR(AVERAGEIF('🔢 Cálculo'!$B$4:$B$203,$A$7,'🔢 Cálculo'!$AC$4:$AC$203),0)+IFERROR(AVERAGEIF('🔢 Cálculo'!$B$4:$B$203,$A$7,'🔢 Cálculo'!$AD$4:$AD$203),0)+IFERROR(AVERAGEIF('🔢 Cálculo'!$B$4:$B$203,$A$7,'🔢 Cálculo'!$AE$4:$AE$203),0))/5,"") -> 0 | E33: =IFERROR((IFERROR((5-AVERAGEIF('🔢 Cálculo'!$B$4:$B$203,$A$7,'🔢 Cálculo'!$AA$4:$AA$203))/4*100,0)+IFERROR((5-AVERAGEIF('🔢 Cálculo'!$B$4:$B$203,$A$7,'🔢 Cálculo'!$AB$4:$AB$203))/4*100,0)+IFERROR((5-AVERAGEIF('🔢 Cálculo'!$B$4:$B$203,$A$7,'🔢 Cálculo'!$AC$4:$AC$203))/4*100,0)+IFERROR((5-AVERAGEIF('🔢 Cálculo'!$B$4:$B$203,$A$7,'🔢 Cálculo'!$AD$4:$AD$203))/4*100,0)+IFERROR((AVERAGEIF('🔢 Cálculo'!$B$4:$B$203,$A$7,'🔢 Cálculo'!$AE$4:$AE$203)-1)/4*100,0))/5,"") -> 0 | F33: =IFERROR(IF(E33="","",IF(E33<25,"Baixo",IF(E33<50,"Moderado",IF(E33<75,"Alto","Crítico")))),"N/A") -> Baixo | G33: =IF(F33="Crítico","🔴 AÇÃO IMEDIATA","") | H33: =IF(F33="Alto","🟠 PRIORITÁRIO","") | I33: =IF(F33="Moderado","⚠️ PLANEJAR","")
A34: =$A$7 -> 0 | B34: Saúde e Bem-Estar | C34: =COUNTIF('🔢 Cálculo'!$B$4:$B$203,$A$7) -> 200 | D34: =IFERROR((IFERROR(AVERAGEIF('🔢 Cálculo'!$B$4:$B$203,$A$7,'🔢 Cálculo'!$AF$4:$AF$203),0)+IFERROR(AVERAGEIF('🔢 Cálculo'!$B$4:$B$203,$A$7,'🔢 Cálculo'!$AG$4:$AG$203),0)+IFERROR(AVERAGEIF('🔢 Cálculo'!$B$4:$B$203,$A$7,'🔢 Cálculo'!$AH$4:$AH$203),0)+IFERROR(AVERAGEIF('🔢 Cálculo'!$B$4:$B$203,$A$7,'🔢 Cálculo'!$AI$4:$AI$203),0)+IFERROR(AVERAGEIF('🔢 Cálculo'!$B$4:$B$203,$A$7,'🔢 Cálculo'!$AJ$4:$AJ$203),0)+IFERROR(AVERAGEIF('🔢 Cálculo'!$B$4:$B$203,$A$7,'🔢 Cálculo'!$AK$4:$AK$203),0)+IFERROR(AVERAGEIF('🔢 Cálculo'!$B$4:$B$203,$A$7,'🔢 Cálculo'!$AL$4:$AL$203),0)+IFERROR(AVERAGEIF('🔢 Cálculo'!$B$4:$B$203,$A$7,'🔢 Cálculo'!$AM$4:$AM$203),0)+IFERROR(AVERAGEIF('🔢 Cálculo'!$B$4:$B$203,$A$7,'🔢 Cálculo'!$AN$4:$AN$203),0))/9,"") -> 0 | E34: =IFERROR((IFERROR((5-AVERAGEIF('🔢 Cálculo'!$B$4:$B$203,$A$7,'🔢 Cálculo'!$AF$4:$AF$203))/4*100,0)+IFERROR((AVERAGEIF('🔢 Cálculo'!$B$4:$B$203,$A$7,'🔢 Cálculo'!$AG$4:$AG$203)-1)/4*100,0)+IFERROR((AVERAGEIF('🔢 Cálculo'!$B$4:$B$203,$A$7,'🔢 Cálculo'!$AH$4:$AH$203)-1)/4*100,0)+IFERROR((AVERAGEIF('🔢 Cálculo'!$B$4:$B$203,$A$7,'🔢 Cálculo'!$AI$4:$AI$203)-1)/4*100,0)+IFERROR((AVERAGEIF('🔢 Cálculo'!$B$4:$B$203,$A$7,'🔢 Cálculo'!$AJ$4:$AJ$203)-1)/4*100,0)+IFERROR((AVERAGEIF('🔢 Cálculo'!$B$4:$B$203,$A$7,'🔢 Cálculo'!$AK$4:$AK$203)-1)/4*100,0)+IFERROR((AVERAGEIF('🔢 Cálculo'!$B$4:$B$203,$A$7,'🔢 Cálculo'!$AL$4:$AL$203)-1)/4*100,0)+IFERROR((AVERAGEIF('🔢 Cálculo'!$B$4:$B$203,$A$7,'🔢 Cálculo'!$AM$4:$AM$203)-1)/4*100,0)+IFERROR((AVERAGEIF('🔢 Cálculo'!$B$4:$B$203,$A$7,'🔢 Cálculo'!$AN$4:$AN$203)-1)/4*100,0))/9,"") -> 0 | F34: =IFERROR(IF(E34="","",IF(E34<25,"Baixo",IF(E34<50,"Moderado",IF(E34<75,"Alto","Crítico")))),"N/A") -> Baixo | G34: =IF(F34="Crítico","🔴 AÇÃO IMEDIATA","") | H34: =IF(F34="Alto","🟠 PRIORITÁRIO","") | I34: =IF(F34="Moderado","⚠️ PLANEJAR","")
A35: =$A$7 -> 0 | B35: Comportamentos Ofensivos | C35: =COUNTIF('🔢 Cálculo'!$B$4:$B$203,$A$7) -> 200 | D35: =IFERROR((IFERROR(AVERAGEIF('🔢 Cálculo'!$B$4:$B$203,$A$7,'🔢 Cálculo'!$AO$4:$AO$203),0)+IFERROR(AVERAGEIF('🔢 Cálculo'!$B$4:$B$203,$A$7,'🔢 Cálculo'!$AP$4:$AP$203),0)+IFERROR(AVERAGEIF('🔢 Cálculo'!$B$4:$B$203,$A$7,'🔢 Cálculo'!$AQ$4:$AQ$203),0)+IFERROR(AVERAGEIF('🔢 Cálculo'!$B$4:$B$203,$A$7,'🔢 Cálculo'!$AR$4:$AR$203),0))/4,"") -> 0 | E35: =IFERROR((IFERROR((AVERAGEIF('🔢 Cálculo'!$B$4:$B$203,$A$7,'🔢 Cálculo'!$AO$4:$AO$203)-1)/4*100,0)+IFERROR((AVERAGEIF('🔢 Cálculo'!$B$4:$B$203,$A$7,'🔢 Cálculo'!$AP$4:$AP$203)-1)/4*100,0)+IFERROR((AVERAGEIF('🔢 Cálculo'!$B$4:$B$203,$A$7,'🔢 Cálculo'!$AQ$4:$AQ$203)-1)/4*100,0)+IFERROR((AVERAGEIF('🔢 Cálculo'!$B$4:$B$203,$A$7,'🔢 Cálculo'!$AR$4:$AR$203)-1)/4*100,0))/4,"") -> 0 | F35: =IFERROR(IF(E35="","",IF(E35<25,"Baixo",IF(E35<50,"Moderado",IF(E35<75,"Alto","Crítico")))),"N/A") -> Baixo | G35: =IF(F35="Crítico","🔴 AÇÃO IMEDIATA","") | H35: =IF(F35="Alto","🟠 PRIORITÁRIO","") | I35: =IF(F35="Moderado","⚠️ PLANEJAR","")
A36: =$A$8 -> 0 | B36: Exigência Laboral | C36: =COUNTIF('🔢 Cálculo'!$B$4:$B$203,$A$8) -> 200 | D36: =IFERROR((IFERROR(AVERAGEIF('🔢 Cálculo'!$B$4:$B$203,$A$8,'🔢 Cálculo'!$D$4:$D$203),0)+IFERROR(AVERAGEIF('🔢 Cálculo'!$B$4:$B$203,$A$8,'🔢 Cálculo'!$E$4:$E$203),0)+IFERROR(AVERAGEIF('🔢 Cálculo'!$B$4:$B$203,$A$8,'🔢 Cálculo'!$F$4:$F$203),0)+IFERROR(AVERAGEIF('🔢 Cálculo'!$B$4:$B$203,$A$8,'🔢 Cálculo'!$G$4:$G$203),0)+IFERROR(AVERAGEIF('🔢 Cálculo'!$B$4:$B$203,$A$8,'🔢 Cálculo'!$H$4:$H$203),0)+IFERROR(AVERAGEIF('🔢 Cálculo'!$B$4:$B$203,$A$8,'🔢 Cálculo'!$I$4:$I$203),0))/6,"") -> 0 | E36: =IFERROR((IFERROR((AVERAGEIF('🔢 Cálculo'!$B$4:$B$203,$A$8,'🔢 Cálculo'!$D$4:$D$203)-1)/4*100,0)+IFERROR((AVERAGEIF('🔢 Cálculo'!$B$4:$B$203,$A$8,'🔢 Cálculo'!$E$4:$E$203)-1)/4*100,0)+IFERROR((AVERAGEIF('🔢 Cálculo'!$B$4:$B$203,$A$8,'🔢 Cálculo'!$F$4:$F$203)-1)/4*100,0)+IFERROR((AVERAGEIF('🔢 Cálculo'!$B$4:$B$203,$A$8,'🔢 Cálculo'!$G$4:$G$203)-1)/4*100,0)+IFERROR((AVERAGEIF('🔢 Cálculo'!$B$4:$B$203,$A$8,'🔢 Cálculo'!$H$4:$H$203)-1)/4*100,0)+IFERROR((AVERAGEIF('🔢 Cálculo'!$B$4:$B$203,$A$8,'🔢 Cálculo'!$I$4:$I$203)-1)/4*100,0))/6,"") -> 0 | F36: =IFERROR(IF(E36="","",IF(E36<25,"Baixo",IF(E36<50,"Moderado",IF(E36<75,"Alto","Crítico")))),"N/A") -> Baixo | G36: =IF(F36="Crítico","🔴 AÇÃO IMEDIATA","") | H36: =IF(F36="Alto","🟠 PRIORITÁRIO","") | I36: =IF(F36="Moderado","⚠️ PLANEJAR","")
A37: =$A$8 -> 0 | B37: Organização do Trabalho | C37: =COUNTIF('🔢 Cálculo'!$B$4:$B$203,$A$8) -> 200 | D37: =IFERROR((IFERROR(AVERAGEIF('🔢 Cálculo'!$B$4:$B$203,$A$8,'🔢 Cálculo'!$J$4:$J$203),0)+IFERROR(AVERAGEIF('🔢 Cálculo'!$B$4:$B$203,$A$8,'🔢 Cálculo'!$K$4:$K$203),0)+IFERROR(AVERAGEIF('🔢 Cálculo'!$B$4:$B$203,$A$8,'🔢 Cálculo'!$L$4:$L$203),0)+IFERROR(AVERAGEIF('🔢 Cálculo'!$B$4:$B$203,$A$8,'🔢 Cálculo'!$M$4:$M$203),0)+IFERROR(AVERAGEIF('🔢 Cálculo'!$B$4:$B$203,$A$8,'🔢 Cálculo'!$N$4:$N$203),0)+IFERROR(AVERAGEIF('🔢 Cálculo'!$B$4:$B$203,$A$8,'🔢 Cálculo'!$O$4:$O$203),0))/6,"") -> 0 | E37: =IFERROR((IFERROR((5-AVERAGEIF('🔢 Cálculo'!$B$4:$B$203,$A$8,'🔢 Cálculo'!$J$4:$J$203))/4*100,0)+IFERROR((5-AVERAGEIF('🔢 Cálculo'!$B$4:$B$203,$A$8,'🔢 Cálculo'!$K$4:$K$203))/4*100,0)+IFERROR((5-AVERAGEIF('🔢 Cálculo'!$B$4:$B$203,$A$8,'🔢 Cálculo'!$L$4:$L$203))/4*100,0)+IFERROR((5-AVERAGEIF('🔢 Cálculo'!$B$4:$B$203,$A$8,'🔢 Cálculo'!$M$4:$M$203))/4*100,0)+IFERROR((5-AVERAGEIF('🔢 Cálculo'!$B$4:$B$203,$A$8,'🔢 Cálculo'!$N$4:$N$203))/4*100,0)+IFERROR((5-AVERAGEIF('🔢 Cálculo'!$B$4:$B$203,$A$8,'🔢 Cálculo'!$O$4:$O$203))/4*100,0))/6,"") -> 0 | F37: =IFERROR(IF(E37="","",IF(E37<25,"Baixo",IF(E37<50,"Moderado",IF(E37<75,"Alto","Crítico")))),"N/A") -> Baixo | G37: =IF(F37="Crítico","🔴 AÇÃO IMEDIATA","") | H37: =IF(F37="Alto","🟠 PRIORITÁRIO","") | I37: =IF(F37="Moderado","⚠️ PLANEJAR","")
